<?xml version="1.0"?>

<robot xmlns:xacro="http://ros.org/wiki/xacro">

  <xacro:include filename="$(find talos_description)/urdf/gripper/gripper.gazebo" />

  <xacro:macro name="talos_gripper" params="name parent reflect">

    <xacro:talos_gripper_gazebo name="${name}"  parent="${parent}" reflect="${reflect}" />
    

    <link name="${name}_base_link">

      <visual>
        <origin xyz="0 0 0" rpy="0 0 0" />
        <geometry>
          <mesh filename="package://talos_description/meshes/gripper/base_link.STL" scale="1 1 1"/>
        </geometry>
        <material name="DarkGrey"/>
      </visual>

      <collision>
        <origin xyz="0 0 0" rpy="0 0 0" />
        <geometry>
          <mesh filename="package://talos_description/meshes/gripper/base_link_collision.STL" scale="1 1 1"/>
        </geometry>
      </collision>

      <inertial>
        <mass value="0.637534"/>
        <inertia ixx="0.0005849692" ixy="4.37159e-06" ixz="-1.2589e-05" iyy="0.00067076439" iyz="2.824361e-05" izz="0.00085526645" />
        <origin rpy="0 0 0" xyz="2.8e-05 0.005394 -0.023654"/>
      </inertial>

    </link>

    <joint name="${name}_base_link_joint" type="fixed">
      <parent link="${parent}"/>
      <child link="${name}_base_link"/>
      <origin xyz="0.00000 0.00000 -0.02875"
              rpy="${0.00000 * deg_to_rad} ${0.00000 * deg_to_rad} ${0.00000 * deg_to_rad}"/>
      <axis xyz="0 0 0" />
    </joint>

    <link name="${name}_motor_double_link">

      <visual>
        <origin xyz="0 0 0" rpy="0 0 0" />
        <geometry>
          <mesh filename="package://talos_description/meshes/gripper/gripper_motor_double.STL" scale="1 1 1"/>
        </geometry>
      <material name="Orange"/>
      </visual>

      <collision>
        <origin xyz="0 0 0" rpy="0 0 0" />
        <geometry>
          <mesh filename="package://talos_description/meshes/gripper/gripper_motor_double_collision.STL" scale="1 1 1"/>
        </geometry>
      </collision>

      <inertial>
        <mass value="0.134356"/>
        <inertia ixx="0.00013479919" ixy="6.184429e-05" ixz="-3.0798e-05" iyy="0.00019602207" iyz="4.707722e-05" izz="0.00024217879" />
        <origin rpy="0 0 0" xyz="0.019654 0.018572 -0.011998"/>
      </inertial>

    </link>

    <joint name="${name}_joint" type="revolute">
      <parent link="${name}_base_link"/>
      <child link="${name}_motor_double_link"/>
      <origin xyz="0.0 0.02025 -0.03"
              rpy="${0.0 * deg_to_rad} ${0.0 * deg_to_rad} ${0.0 * deg_to_rad}"/>
      <axis xyz="1 0 0" />
      <limit lower="${-55.0 * deg_to_rad}" upper="${0.0 * deg_to_rad}" effort="1.0" velocity="1.0" />
      <dynamics friction="1.0" damping="1.0"/>
    </joint>

    <link name="${name}_inner_double_link">

      <visual>
        <origin xyz="0 0 0" rpy="0 0 0" />
        <geometry>
          <mesh filename="package://talos_description/meshes/gripper/inner_double.STL" scale="1 1 1"/>
        </geometry>
      <material name="Orange"/>
      </visual>

      <collision>
        <origin xyz="0 0 0" rpy="0 0 0" />
        <geometry>
          <mesh filename="package://talos_description/meshes/gripper/inner_double_collision.STL" scale="1 1 1"/>
        </geometry>
      </collision>

      <inertial>
        <mass value="0.087986"/>
        <inertia ixx="7.410642e-05" ixy="-7.4773e-07" ixz="1.01536e-06" iyy="0.0001279418" iyz="2.504083e-05" izz="0.00010495175" />
        <origin rpy="0 0 0" xyz="-0.013283 0.036852 -0.023153"/>
      </inertial>

    </link>

    <joint name="${name}_inner_double_joint" type="revolute">
      <parent link="${name}_base_link"/>
      <child link="${name}_inner_double_link"/>
      <origin xyz="0.00000 0.00525 -0.05598"
              rpy="${0.00000 * deg_to_rad} ${0.00000 * deg_to_rad} ${0.00000 * deg_to_rad}"/>
      <axis xyz="1 0 0" />
      <limit lower="${-60.0 * deg_to_rad}" upper="${0.0 * deg_to_rad}" effort="100.0" velocity="1.0" />
      <mimic joint="${name}_joint" multiplier="${1.0}" offset="0.0" />
    </joint>

    <link name="${name}_fingertip_1_link">

      <visual>
        <origin xyz="0 0 0" rpy="0 0 0" />
        <geometry>
          <mesh filename="package://talos_description/meshes/gripper/fingertip.STL" scale="1 1 1"/>
        </geometry>
      <material name="DarkGrey"/>
      </visual>

      <collision>
        <origin xyz="0 0 0" rpy="0 0 0" />
        <geometry>
          <mesh filename="package://talos_description/meshes/gripper/fingertip_collision.STL" scale="1 1 1"/>
        </geometry>
      </collision>

      <inertial>
        <mass value="0.026301"/>
        <inertia ixx="8e-06" ixy="0" ixz="0" iyy="8.69179e-06" iyz="-1.43612e-06" izz="2.3082e-06" />
        <origin rpy="0 0 0" xyz="0 0.004604 -0.002537"/>
      </inertial>

    </link>

    <joint name="${name}_fingertip_1_joint" type="revolute">
      <parent link="${name}_inner_double_link"/>
      <child link="${name}_fingertip_1_link"/>
      <origin xyz="0.03200 0.04589 -0.06553"
              rpy="${0.00000 * deg_to_rad} ${0.00000 * deg_to_rad} ${0.00000 * deg_to_rad}"/>
      <axis xyz="1 0 0" />
      <limit lower="${0.0 * deg_to_rad}" upper="${60.0 * deg_to_rad}" effort="100.0" velocity="1.0" />
      <mimic joint="${name}_joint" multiplier="${-1.0}" offset="0.0" />
    </joint>

    <link name="${name}_fingertip_2_link">
     
      <visual>
        <origin xyz="0 0 0" rpy="0 0 0" />
        <geometry>
          <mesh filename="package://talos_description/meshes/gripper/fingertip.STL" scale="1 1 1"/>
        </geometry>
        <material name="DarkGrey"/>
      </visual>

      <collision>
        <origin xyz="0 0 0" rpy="0 0 0" />
        <geometry>
          <mesh filename="package://talos_description/meshes/gripper/fingertip_collision.STL" scale="1 1 1"/>
        </geometry>
      </collision>

      <inertial>
        <mass value="0.026301"/>
        <inertia ixx="8e-06" ixy="0" ixz="0" iyy="8.69179e-06" iyz="-1.43612e-06" izz="2.3082e-06" />
        <origin rpy="0 0 0" xyz="0 0.004604 -0.002537"/>
      </inertial>

    </link>

    <joint name="${name}_fingertip_2_joint" type="revolute">
      <parent link="${name}_inner_double_link"/>
      <child link="${name}_fingertip_2_link"/>
      <origin xyz="-0.03200 0.04589 -0.06553"
              rpy="${0.00000 * deg_to_rad} ${0.00000 * deg_to_rad} ${0.00000 * deg_to_rad}"/>
      <axis xyz="1 0 0" />
      <limit lower="${0.0 * deg_to_rad}" upper="${60.0 * deg_to_rad}" effort="100.0" velocity="1.0" />
      <mimic joint="${name}_joint" multiplier="${-1.0}" offset="0.0" />
    </joint>

    <link name="${name}_motor_single_link">
     
      <visual>
        <origin xyz="0 0 0" rpy="0 0 0" />
        <geometry>
          <mesh filename="package://talos_description/meshes/gripper/gripper_motor_single.STL" scale="1 1 1"/>
        </geometry>
      <material name="Orange"/>
      </visual>

      <collision>
        <origin xyz="0 0 0" rpy="0 0 0" />
        <geometry>
          <mesh filename="package://talos_description/meshes/gripper/gripper_motor_single_collision.STL" scale="1 1 1"/>
        </geometry>
      </collision>

      <inertial>
        <mass value="0.107923"/>
        <inertia ixx="8.973662e-05" ixy="-4.082027e-05" ixz="-1.927099e-05" iyy="0.00011957255" iyz="-2.873284e-05" izz="0.00015469079" />
        <origin rpy="0 0 0" xyz="0.025237 -0.011231 -0.008158"/>
      </inertial>

    </link>

    <joint name="${name}_motor_single_joint" type="revolute">
      <parent link="${name}_base_link"/>
      <child link="${name}_motor_single_link"/>
      <origin xyz="0.00000 -0.02025 -0.03000"
              rpy="${0.00000 * deg_to_rad} ${0.00000 * deg_to_rad} ${0.00000 * deg_to_rad}"/>
      <axis xyz="1 0 0" />
      <limit lower="${0.0 * deg_to_rad}" upper="${60.0 * deg_to_rad}" effort="100.0" velocity="1.0" />
      <mimic joint="${name}_joint" multiplier="${-1.0}" offset="0.0" />
    </joint>

    <link name="${name}_inner_single_link">

      <visual>
        <origin xyz="0 0 0" rpy="0 0 0" />
        <geometry>
          <mesh filename="package://talos_description/meshes/gripper/inner_single.STL" scale="1 1 1"/>
        </geometry>
      <material name="Orange"/>
      </visual>

      <collision>
        <origin xyz="0 0 0" rpy="0 0 0" />
        <geometry>
          <mesh filename="package://talos_description/meshes/gripper/inner_single_collision.STL" scale="1 1 1"/>
        </geometry>
      </collision>

      <inertial>
        <mass value="0.047177"/>
        <inertia ixx="4.199818e-05" ixy="1.3418e-07" ixz="1.9358e-07" iyy="3.231338e-05" iyz="-1.509136e-05" izz="2.168842e-05" />
        <origin rpy="0 0 0" xyz="0 -0.034565 -0.021412"/>
      </inertial>

    </link>

    <joint name="${name}_inner_single_joint" type="revolute">
      <parent link="${name}_base_link"/>
      <child link="${name}_inner_single_link"/>
      <origin xyz="0.00000 -0.00525 -0.05598"
              rpy="${0.00000 * deg_to_rad} ${0.00000 * deg_to_rad} ${0.00000 * deg_to_rad}"/>
      <axis xyz="1 0 0" />
      <limit lower="${0.0 * deg_to_rad}" upper="${60.0 * deg_to_rad}" effort="100.0" velocity="1.0" />
      <mimic joint="${name}_joint" multiplier="${-1.0}" offset="0.0" />
    </joint>


    <link name="${name}_fingertip_3_link">

      <visual>
        <origin xyz="0 0 0" rpy="0 0 0" />
        <geometry>
          <mesh filename="package://talos_description/meshes/gripper/fingertip.STL" scale="1 1 1"/>
        </geometry>
      <material name="DarkGrey"/>
      </visual>

      <collision>
        <origin xyz="0 0 0" rpy="0 0 0" />
        <geometry>
          <mesh filename="package://talos_description/meshes/gripper/fingertip_collision.STL" scale="1 1 1"/>
        </geometry>
      </collision>

      <inertial>
        <mass value="0.026301"/>
        <inertia ixx="8e-06" ixy="0" ixz="0" iyy="8.69179e-06" iyz="-1.43612e-06" izz="2.3082e-06" />
        <origin rpy="0 0 0" xyz="0 0.004604 -0.002537"/>
      </inertial>

    </link>

    <joint name="${name}_fingertip_3_joint" type="revolute">
      <parent link="${name}_inner_single_link"/>
      <child link="${name}_fingertip_3_link"/>
      <origin xyz="0.00000 -0.04589 -0.06553"
              rpy="${0.00000 * deg_to_rad} ${0.00000 * deg_to_rad} ${180.00000 * deg_to_rad}"/>
      <axis xyz="1 0 0" />
      <limit lower="${0.0 * deg_to_rad}" upper="${60.0 * deg_to_rad}" effort="100.0" velocity="1.0" />
      <mimic joint="${name}_joint" multiplier="${-1.0}" offset="0.0" />
    </joint>
  
    <transmission name="${name}_trans">
      <type>transmission_interface/SimpleTransmission</type>
      <actuator name="${name}_motor" >
        <mechanicalReduction>1.0</mechanicalReduction>
        <hardwareInterface>hardware_interface/EffortJointInterface</hardwareInterface>
      </actuator>
      <joint name="${name}_joint" >
        <hardwareInterface>hardware_interface/EffortJointInterface</hardwareInterface>
      </joint>
    </transmission>

</xacro:macro>

</robot>
