<?xml version="1.0"?>
<robot xmlns:xacro="http://ros.org/wiki/xacro">

  <!--Constant parameters-->
  <xacro:property name="head_friction" value="1.0" />
  <xacro:property name="head_damping"  value="0.5" />
  <xacro:property name="head_max_vel"  value="3.0" />
  <xacro:property name="head_eps"      value="0.02" />

  <xacro:include filename="$(find talos_description)/urdf/head/head.gazebo" />


  <link name="neck_link">
     
    <visual>
      <origin xyz="0 0 0" rpy="0 0 0" />
      <geometry>
        <mesh filename="package://talos_description/meshes/head/neck.stl" scale="1 1 1"/>
      </geometry>
      <material name="DarkGrey" />
    </visual>

    <collision>
      <origin xyz="0 0 0" rpy="0 0 0" />
      <geometry>
        <mesh filename="package://talos_description/meshes/head/neck_collision.stl" scale="1 1 1"/>
      </geometry>
    </collision>

    <inertial>
      <mass value="0.73746"/>
      <inertia ixx="0.00224878584" ixy="4.69375e-06" ixz="8.55557e-05" iyy="0.00111158492" iyz="-4.132536e-05" izz="0.00205225921" />
      <origin rpy="0 0 0" xyz="-0.00157211 -0.00157919 0.02175767"/>
    </inertial>


  </link>


  <joint name="updown_head_joint" type="revolute">
    
    <parent link="chest_link"/>
    <child link="neck_link"/>
    <origin xyz="0.02000 0.00000 0.32100"
            rpy="${0.00000 * deg_to_rad} ${0.00000 * deg_to_rad} ${0.00000 * deg_to_rad}"/>
    <axis xyz="0 1 0" />
    <limit lower="${-12.00000 * deg_to_rad}" upper="${45.00000 * deg_to_rad}" effort="8.0" velocity="${head_max_vel}" />
    <dynamics damping="${head_damping}" friction="${head_friction}"/>

  </joint>

 
  <link name="cranium_link">

    <visual>
      <origin xyz="0 0 0" rpy="0 0 0" />
      <geometry>
        <mesh filename="package://talos_description/meshes/head/cranium.stl" scale="1 1 1"/>
      </geometry>
      <material name="LightGrey" />
    </visual>

    <collision>
      <origin xyz="0 0 0" rpy="0 0 0" />
      <geometry>
        <mesh filename="package://talos_description/meshes/head/cranium_collision.stl" scale="1 1 1"/>
      </geometry>
    </collision>

    <inertial>
      <mass value="1.443954"/>
      <inertia ixx="0.01084624339" ixy="1.050889e-05" ixz="0.00041594252" iyy="0.0109569176" iyz="2.367831e-05" izz="0.00571698895" />
      <origin rpy="0 0 0" xyz="0.01002657 5.218e-05 0.14136068"/>
    </inertial>

  </link>

  <joint name="leftright_head_joint" type="revolute">
    
    <parent link="neck_link"/>
    <child link="cranium_link"/>
    <origin xyz="0.00000 0.00000 0.00000"
            rpy="${0.00000 * deg_to_rad} ${0.00000 * deg_to_rad} ${0.00000 * deg_to_rad}"/>
    <axis xyz="0 0 1" />
    <limit lower="${-75.00000 * deg_to_rad}" upper="${75.00000 * deg_to_rad}" effort="4.0" velocity="${head_max_vel}" />
    <dynamics damping="${head_damping}" friction="${head_friction}"/>

  </joint>

  <transmission name="updown_head_trans">
    <type>transmission_interface/SimpleTransmission</type>
     <joint name="updown_head_joint">
      <mechanicalReduction>1.0</mechanicalReduction>
      <hardwareInterface>hardware_interface/EffortJointInterface</hardwareInterface>
    </joint>
    <actuator name="neck_motor">
      <hardwareInterface>hardware_interface/EffortJointInterface</hardwareInterface>
      <mechanicalReduction>1.0</mechanicalReduction>
    </actuator>
  </transmission>

  <transmission name="leftright_head_trans"> 
    <type>transmission_interface/SimpleTransmission</type>
    <joint name="leftright_head_joint">
      <mechanicalReduction>2.0</mechanicalReduction>
      <hardwareInterface>hardware_interface/EffortJointInterface</hardwareInterface>
    </joint>
    <actuator name="cranium_motor">  
      <mechanicalReduction>1.0</mechanicalReduction>
      <hardwareInterface>hardware_interface/EffortJointInterface</hardwareInterface>
    </actuator> 
  </transmission>

</robot>
