<?xml version="1.0" ?>
<!-- =================================================================================== -->
<!-- |    This document was autogenerated by xacro from talos.xacro                    | -->
<!-- |    EDITING THIS FILE BY HAND IS NOT RECOMMENDED                                 | -->
<!-- =================================================================================== -->
<robot name="talos">
  <!-- End of common part -->
  <!-- <xacro:include filename="$(find talos_description)/urdf/torso/torso.xacro" />
  
  <xacro:include filename="$(find talos_description)/urdf/sensors/imu.xacro" />


  <xacro:include filename="$(find talos_description)/urdf/head/head.xacro" /> 

  <xacro:include filename="$(find talos_description)/urdf/sensors/orbbec_astra_pro.xacro" />

  <xacro:include filename="$(find talos_description)/urdf/arm/arm.xacro" />

  <xacro:include filename="$(find talos_description)/urdf/arm/wrist.xacro" />

  <xacro:include filename="$(find talos_description)/urdf/sensors/ft_sensor.xacro" /> -->
  <!-- <xacro:talos_arm name="arm" parent="chest_link" side="left" reflect="1"/>
  <xacro:talos_wrist name="arm" parent="arm_left_4_link" side="left" reflect="1" />

  <xacro:talos_arm name="arm" parent="chest_link" side="right" reflect="-1"/> 
  <xacro:talos_wrist name="arm" parent="arm_right_4_link" side="right" reflect="-1" />  
  
  <xacro:ft_sensor name="wrist" parent="arm_right_7_link" side="right" reflect="1"  />
  <xacro:ft_sensor name="wrist" parent="arm_left_7_link"  side="left"  reflect="-1" />
  
  <xacro:talos_gripper name="gripper_left" parent="wrist_left_ft_tool_link" reflect="1" /> -->
  <link name="dummy_base_link"/>
  <gazebo>
    <plugin filename="libroboticsgroup_upatras_gazebo_mimic_joint_plugin.so" name="mimic_gripper_right_inner_double_joint">
      <joint>gripper_right_joint</joint>
      <mimicJoint>gripper_right_inner_double_joint</mimicJoint>
      <multiplier>1.0</multiplier>
      <offset>0.0</offset>
      <hasPID/>
    </plugin>
    <plugin filename="libroboticsgroup_upatras_gazebo_mimic_joint_plugin.so" name="mimic_gripper_right_fingertip_1_joint">
      <joint>gripper_right_joint</joint>
      <mimicJoint>gripper_right_fingertip_1_joint</mimicJoint>
      <multiplier>-1.0</multiplier>
      <offset>0.0</offset>
      <hasPID/>
    </plugin>
    <plugin filename="libroboticsgroup_upatras_gazebo_mimic_joint_plugin.so" name="mimic_gripper_right_fingertip_2_joint">
      <joint>gripper_right_joint</joint>
      <mimicJoint>gripper_right_fingertip_2_joint</mimicJoint>
      <multiplier>-1.0</multiplier>
      <offset>0.0</offset>
      <hasPID/>
    </plugin>
    <plugin filename="libroboticsgroup_upatras_gazebo_mimic_joint_plugin.so" name="mimic_gripper_right_inner_single_joint">
      <joint>gripper_right_joint</joint>
      <mimicJoint>gripper_right_inner_single_joint</mimicJoint>
      <multiplier>-1.0</multiplier>
      <offset>0.0</offset>
      <hasPID/>
    </plugin>
    <plugin filename="libroboticsgroup_upatras_gazebo_mimic_joint_plugin.so" name="mimic_gripper_right_motor_single_joint">
      <joint>gripper_right_joint</joint>
      <mimicJoint>gripper_right_motor_single_joint</mimicJoint>
      <multiplier>-1.0</multiplier>
      <offset>0.0</offset>
      <hasPID/>
    </plugin>
    <plugin filename="libroboticsgroup_upatras_gazebo_mimic_joint_plugin.so" name="mimic_gripper_right_fingertip_3_joint">
      <joint>gripper_right_joint</joint>
      <mimicJoint>gripper_right_fingertip_3_joint</mimicJoint>
      <multiplier>-1.0</multiplier>
      <offset>0.0</offset>
      <hasPID/>
    </plugin>
  </gazebo>
  <gazebo reference="gripper_right_joint">
    <implicitSpringDamper>1</implicitSpringDamper>
    <provideFeedback>1</provideFeedback>
  </gazebo>
  <gazebo reference="gripper_right_inner_double_joint">
    <implicitSpringDamper>1</implicitSpringDamper>
    <provideFeedback>1</provideFeedback>
  </gazebo>
  <gazebo reference="gripper_right_fingertip_1_joint">
    <implicitSpringDamper>1</implicitSpringDamper>
    <provideFeedback>1</provideFeedback>
  </gazebo>
  <gazebo reference="gripper_right_fingertip_2_joint">
    <implicitSpringDamper>1</implicitSpringDamper>
    <provideFeedback>1</provideFeedback>
  </gazebo>
  <gazebo reference="gripper_right_motor_single_joint">
    <implicitSpringDamper>1</implicitSpringDamper>
    <provideFeedback>1</provideFeedback>
  </gazebo>
  <gazebo reference="gripper_right_fingertip_3_joint">
    <implicitSpringDamper>1</implicitSpringDamper>
    <provideFeedback>1</provideFeedback>
  </gazebo>
  <gazebo reference="gripper_right_base_link">
    <material>Gazebo/FlatBlack</material>
  </gazebo>
  <gazebo reference="gripper_right_motor_double_link">
    <material>Gazebo/Orange</material>
  </gazebo>
  <gazebo reference="gripper_right_inner_double_link">
    <material>Gazebo/Orange</material>
  </gazebo>
  <gazebo reference="gripper_right_fingertip_1_link">
    <material>Gazebo/FlatBlack</material>
  </gazebo>
  <gazebo reference="gripper_right_motor_single_link">
    <material>Gazebo/Orange</material>
  </gazebo>
  <gazebo reference="gripper_right_inner_single_link">
    <material>Gazebo/Orange</material>
  </gazebo>
  <gazebo reference="gripper_right_fingertip_2_link">
    <material>Gazebo/FlatBlack</material>
  </gazebo>
  <gazebo reference="gripper_right_fingertip_3_link">
    <material>Gazebo/FlatBlack</material>
  </gazebo>
  <link name="gripper_right_base_link">
    <visual>
      <origin rpy="0 0 0" xyz="0 0 0"/>
      <geometry>
        <mesh filename="package://talos_description/meshes/gripper/base_link.STL" scale="1 1 1"/>
      </geometry>
      <material name="DarkGrey"/>
    </visual>
    <collision>
      <origin rpy="0 0 0" xyz="0 0 0"/>
      <geometry>
        <mesh filename="package://talos_description/meshes/gripper/base_link_collision.STL" scale="1 1 1"/>
      </geometry>
    </collision>
    <inertial>
      <mass value="0.637534"/>
      <inertia ixx="0.0005849692" ixy="4.37159e-06" ixz="-1.2589e-05" iyy="0.00067076439" iyz="2.824361e-05" izz="0.00085526645"/>
      <origin rpy="0 0 0" xyz="2.8e-05 0.005394 -0.023654"/>
    </inertial>
  </link>
  <joint name="gripper_right_base_link_joint" type="fixed">
    <parent link="dummy_base_link"/>
    <child link="gripper_right_base_link"/>
    <origin rpy="0.0 0.0 0.0" xyz="0.00000 0.00000 -0.02875"/>
    <axis xyz="0 0 0"/>
  </joint>
  <link name="gripper_right_motor_double_link">
    <visual>
      <origin rpy="0 0 0" xyz="0 0 0"/>
      <geometry>
        <mesh filename="package://talos_description/meshes/gripper/gripper_motor_double.STL" scale="1 1 1"/>
      </geometry>
      <material name="Orange"/>
    </visual>
    <collision>
      <origin rpy="0 0 0" xyz="0 0 0"/>
      <geometry>
        <mesh filename="package://talos_description/meshes/gripper/gripper_motor_double_collision.STL" scale="1 1 1"/>
      </geometry>
    </collision>
    <inertial>
      <mass value="0.134356"/>
      <inertia ixx="0.00013479919" ixy="6.184429e-05" ixz="-3.0798e-05" iyy="0.00019602207" iyz="4.707722e-05" izz="0.00024217879"/>
      <origin rpy="0 0 0" xyz="0.019654 0.018572 -0.011998"/>
    </inertial>
  </link>
  <joint name="gripper_right_joint" type="revolute">
    <parent link="gripper_right_base_link"/>
    <child link="gripper_right_motor_double_link"/>
    <origin rpy="0.0 0.0 0.0" xyz="0.0 0.02025 -0.03"/>
    <axis xyz="1 0 0"/>
    <limit effort="1.0" lower="-0.9599310885968813" upper="0.0" velocity="1.0"/>
    <dynamics damping="1.0" friction="1.0"/>
  </joint>
  <link name="gripper_right_inner_double_link">
    <visual>
      <origin rpy="0 0 0" xyz="0 0 0"/>
      <geometry>
        <mesh filename="package://talos_description/meshes/gripper/inner_double.STL" scale="1 1 1"/>
      </geometry>
      <material name="Orange"/>
    </visual>
    <collision>
      <origin rpy="0 0 0" xyz="0 0 0"/>
      <geometry>
        <mesh filename="package://talos_description/meshes/gripper/inner_double_collision.STL" scale="1 1 1"/>
      </geometry>
    </collision>
    <inertial>
      <mass value="0.087986"/>
      <inertia ixx="7.410642e-05" ixy="-7.4773e-07" ixz="1.01536e-06" iyy="0.0001279418" iyz="2.504083e-05" izz="0.00010495175"/>
      <origin rpy="0 0 0" xyz="-0.013283 0.036852 -0.023153"/>
    </inertial>
  </link>
  <joint name="gripper_right_inner_double_joint" type="revolute">
    <parent link="gripper_right_base_link"/>
    <child link="gripper_right_inner_double_link"/>
    <origin rpy="0.0 0.0 0.0" xyz="0.00000 0.00525 -0.05598"/>
    <axis xyz="1 0 0"/>
    <limit effort="100.0" lower="-1.0471975511965976" upper="0.0" velocity="1.0"/>
    <mimic joint="gripper_right_joint" multiplier="1.0" offset="0.0"/>
  </joint>
  <link name="gripper_right_fingertip_1_link">
    <visual>
      <origin rpy="0 0 0" xyz="0 0 0"/>
      <geometry>
        <mesh filename="package://talos_description/meshes/gripper/fingertip.STL" scale="1 1 1"/>
      </geometry>
      <material name="DarkGrey"/>
    </visual>
    <collision>
      <origin rpy="0 0 0" xyz="0 0 0"/>
      <geometry>
        <mesh filename="package://talos_description/meshes/gripper/fingertip_collision.STL" scale="1 1 1"/>
      </geometry>
    </collision>
    <inertial>
      <mass value="0.026301"/>
      <inertia ixx="8e-06" ixy="0" ixz="0" iyy="8.69179e-06" iyz="-1.43612e-06" izz="2.3082e-06"/>
      <origin rpy="0 0 0" xyz="0 0.004604 -0.002537"/>
    </inertial>
  </link>
  <joint name="gripper_right_fingertip_1_joint" type="revolute">
    <parent link="gripper_right_inner_double_link"/>
    <child link="gripper_right_fingertip_1_link"/>
    <origin rpy="0.0 0.0 0.0" xyz="0.03200 0.04589 -0.06553"/>
    <axis xyz="1 0 0"/>
    <limit effort="100.0" lower="0.0" upper="1.0471975511965976" velocity="1.0"/>
    <mimic joint="gripper_right_joint" multiplier="-1.0" offset="0.0"/>
  </joint>
  <link name="gripper_right_fingertip_2_link">
    <visual>
      <origin rpy="0 0 0" xyz="0 0 0"/>
      <geometry>
        <mesh filename="package://talos_description/meshes/gripper/fingertip.STL" scale="1 1 1"/>
      </geometry>
      <material name="DarkGrey"/>
    </visual>
    <collision>
      <origin rpy="0 0 0" xyz="0 0 0"/>
      <geometry>
        <mesh filename="package://talos_description/meshes/gripper/fingertip_collision.STL" scale="1 1 1"/>
      </geometry>
    </collision>
    <inertial>
      <mass value="0.026301"/>
      <inertia ixx="8e-06" ixy="0" ixz="0" iyy="8.69179e-06" iyz="-1.43612e-06" izz="2.3082e-06"/>
      <origin rpy="0 0 0" xyz="0 0.004604 -0.002537"/>
    </inertial>
  </link>
  <joint name="gripper_right_fingertip_2_joint" type="revolute">
    <parent link="gripper_right_inner_double_link"/>
    <child link="gripper_right_fingertip_2_link"/>
    <origin rpy="0.0 0.0 0.0" xyz="-0.03200 0.04589 -0.06553"/>
    <axis xyz="1 0 0"/>
    <limit effort="100.0" lower="0.0" upper="1.0471975511965976" velocity="1.0"/>
    <mimic joint="gripper_right_joint" multiplier="-1.0" offset="0.0"/>
  </joint>
  <link name="gripper_right_motor_single_link">
    <visual>
      <origin rpy="0 0 0" xyz="0 0 0"/>
      <geometry>
        <mesh filename="package://talos_description/meshes/gripper/gripper_motor_single.STL" scale="1 1 1"/>
      </geometry>
      <material name="Orange"/>
    </visual>
    <collision>
      <origin rpy="0 0 0" xyz="0 0 0"/>
      <geometry>
        <mesh filename="package://talos_description/meshes/gripper/gripper_motor_single_collision.STL" scale="1 1 1"/>
      </geometry>
    </collision>
    <inertial>
      <mass value="0.107923"/>
      <inertia ixx="8.973662e-05" ixy="-4.082027e-05" ixz="-1.927099e-05" iyy="0.00011957255" iyz="-2.873284e-05" izz="0.00015469079"/>
      <origin rpy="0 0 0" xyz="0.025237 -0.011231 -0.008158"/>
    </inertial>
  </link>
  <joint name="gripper_right_motor_single_joint" type="revolute">
    <parent link="gripper_right_base_link"/>
    <child link="gripper_right_motor_single_link"/>
    <origin rpy="0.0 0.0 0.0" xyz="0.00000 -0.02025 -0.03000"/>
    <axis xyz="1 0 0"/>
    <limit effort="100.0" lower="0.0" upper="1.0471975511965976" velocity="1.0"/>
    <mimic joint="gripper_right_joint" multiplier="-1.0" offset="0.0"/>
  </joint>
  <link name="gripper_right_inner_single_link">
    <visual>
      <origin rpy="0 0 0" xyz="0 0 0"/>
      <geometry>
        <mesh filename="package://talos_description/meshes/gripper/inner_single.STL" scale="1 1 1"/>
      </geometry>
      <material name="Orange"/>
    </visual>
    <collision>
      <origin rpy="0 0 0" xyz="0 0 0"/>
      <geometry>
        <mesh filename="package://talos_description/meshes/gripper/inner_single_collision.STL" scale="1 1 1"/>
      </geometry>
    </collision>
    <inertial>
      <mass value="0.047177"/>
      <inertia ixx="4.199818e-05" ixy="1.3418e-07" ixz="1.9358e-07" iyy="3.231338e-05" iyz="-1.509136e-05" izz="2.168842e-05"/>
      <origin rpy="0 0 0" xyz="0 -0.034565 -0.021412"/>
    </inertial>
  </link>
  <joint name="gripper_right_inner_single_joint" type="revolute">
    <parent link="gripper_right_base_link"/>
    <child link="gripper_right_inner_single_link"/>
    <origin rpy="0.0 0.0 0.0" xyz="0.00000 -0.00525 -0.05598"/>
    <axis xyz="1 0 0"/>
    <limit effort="100.0" lower="0.0" upper="1.0471975511965976" velocity="1.0"/>
    <mimic joint="gripper_right_joint" multiplier="-1.0" offset="0.0"/>
  </joint>
  <link name="gripper_right_fingertip_3_link">
    <visual>
      <origin rpy="0 0 0" xyz="0 0 0"/>
      <geometry>
        <mesh filename="package://talos_description/meshes/gripper/fingertip.STL" scale="1 1 1"/>
      </geometry>
      <material name="DarkGrey"/>
    </visual>
    <collision>
      <origin rpy="0 0 0" xyz="0 0 0"/>
      <geometry>
        <mesh filename="package://talos_description/meshes/gripper/fingertip_collision.STL" scale="1 1 1"/>
      </geometry>
    </collision>
    <inertial>
      <mass value="0.026301"/>
      <inertia ixx="8e-06" ixy="0" ixz="0" iyy="8.69179e-06" iyz="-1.43612e-06" izz="2.3082e-06"/>
      <origin rpy="0 0 0" xyz="0 0.004604 -0.002537"/>
    </inertial>
  </link>
  <joint name="gripper_right_fingertip_3_joint" type="revolute">
    <parent link="gripper_right_inner_single_link"/>
    <child link="gripper_right_fingertip_3_link"/>
    <origin rpy="0.0 0.0 3.141592653589793" xyz="0.00000 -0.04589 -0.06553"/>
    <axis xyz="1 0 0"/>
    <limit effort="100.0" lower="0.0" upper="1.0471975511965976" velocity="1.0"/>
    <mimic joint="gripper_right_joint" multiplier="-1.0" offset="0.0"/>
  </joint>
  <transmission name="gripper_right_trans">
    <type>transmission_interface/SimpleTransmission</type>
    <actuator name="gripper_right_motor">
      <mechanicalReduction>1.0</mechanicalReduction>
      <hardwareInterface>hardware_interface/EffortJointInterface</hardwareInterface>
    </actuator>
    <joint name="gripper_right_joint">
      <hardwareInterface>hardware_interface/EffortJointInterface</hardwareInterface>
    </joint>
  </transmission>
  <gazebo>
    <plugin filename="libgazebo_ros_control.so" name="gazebo_ros_control">
      <robotNamespace>/talos</robotNamespace>
      <robotSimType>gazebo_ros_control/DefaultRobotHWSim</robotSimType>
    </plugin>
  </gazebo>
  <material name="Blue">
    <color rgba="0.0 0.0 0.8 1.0"/>
  </material>
  <material name="Green">
    <color rgba="0.0 0.8 0.0 1.0"/>
  </material>
  <material name="Grey">
    <color rgba="0.7 0.7 0.7 1.0"/>
  </material>
  <material name="LightGrey">
    <color rgba="0.9 0.9 0.9 1.0"/>
  </material>
  <material name="DarkGrey">
    <color rgba="0.2 0.2 0.2 1.0"/>
  </material>
  <material name="Red">
    <color rgba="0.8 0.0 0.0 1.0"/>
  </material>
  <material name="White">
    <color rgba="1.0 1.0 1.0 1.0"/>
  </material>
  <material name="Orange">
    <color rgba="1.0 0.5 0.0 1.0"/>
  </material>
  <material name="FlatBlack">
    <color rgba="1.0 0.0 0.0 0.0"/>
  </material>
</robot>

