<?xml version="1.0" ?>
<!-- =================================================================================== -->
<!-- |    This document was autogenerated by xacro from src/talos_description/urdf/talos.urdf.xacro | -->
<!-- |    EDITING THIS FILE BY HAND IS NOT RECOMMENDED                                 | -->
<!-- =================================================================================== -->
<robot name="talos">
  <!-- End of common part -->
  <gazebo reference="chest_link">
    <mu1>0.9</mu1>
    <mu2>0.9</mu2>
  </gazebo>
  <gazebo reference="waist_link">
    <mu1>0.9</mu1>
    <mu2>0.9</mu2>
  </gazebo>
  <gazebo reference="hip_link">
    <mu1>0.9</mu1>
    <mu2>0.9</mu2>
  </gazebo>
  <gazebo reference="hip_waist_joint">
    <implicitSpringDamper>1</implicitSpringDamper>
  </gazebo>
  <gazebo reference="waist_chest_joint">
    <implicitSpringDamper>1</implicitSpringDamper>
    <provideFeedback>1</provideFeedback>
  </gazebo>
  <link name="chest_link">
    <visual>
      <origin rpy="0 0 0" xyz="0 0 0"/>
      <geometry>
        <mesh filename="package://talos_description/meshes/torso/chest.STL" scale="1 1 1"/>
      </geometry>
      <material name="LightGrey"/>
    </visual>
    <collision>
      <origin rpy="0 0 0" xyz="0 0 0"/>
      <geometry>
        <mesh filename="package://talos_description/meshes/torso/chest_collision.STL" scale="1 1 1"/>
      </geometry>
    </collision>
    <inertial>
      <mass value="16.97403"/>
      <inertia ixx="0.44372633826" ixy="0.00069132133" ixz="-0.01218206353" iyy="0.2998576068" iyz="-0.00019623338" izz="0.32201554742"/>
      <origin rpy="0 0 0" xyz="-0.0463563 -0.00099023 0.1452805"/>
    </inertial>
  </link>
  <link name="waist_link">
    <visual>
      <origin rpy="0 0 0" xyz="0 0 0"/>
      <geometry>
        <mesh filename="package://talos_description/meshes/torso/waist.STL" scale="1 1 1"/>
      </geometry>
      <material name="LightGrey"/>
    </visual>
    <collision>
      <origin rpy="0 0 0" xyz="0 0 0"/>
      <geometry>
        <mesh filename="package://talos_description/meshes/torso/waist.STL" scale="1 1 1"/>
      </geometry>
    </collision>
    <inertial>
      <mass value="2.294658"/>
      <inertia ixx="0.00638508087" ixy="-7.107e-08" ixz="-3.065592e-05" iyy="0.00410256102" iyz="-1.46946e-06" izz="0.00622968815"/>
      <origin rpy="0 0 0" xyz="0.00078223 3.528e-05 -0.01782457"/>
    </inertial>
  </link>
  <link name="base_link">
    <visual>
      <origin rpy="0 0 0" xyz="0 0 0"/>
      <geometry>
        <mesh filename="package://talos_description/meshes/torso/base_link.STL" scale="1 1 1"/>
      </geometry>
      <material name="LightGrey"/>
    </visual>
    <collision>
      <origin rpy="0 0 0" xyz="0 0 0"/>
      <geometry>
        <mesh filename="package://talos_description/meshes/torso/base_link_collision.STL" scale="1 1 1"/>
      </geometry>
    </collision>
    <inertial>
      <mass value="0.637534"/>
      <inertia ixx="0.0005849692" ixy="4.37159e-06" ixz="-1.2589e-05" iyy="0.00067076439" iyz="2.824361e-05" izz="0.00085526645"/>
      <origin rpy="0 0 0" xyz="2.8e-05 0.005394 -0.023654"/>
    </inertial>
  </link>
  <!-- <link name="base_link" />

    <joint name="base_to_hip_link" type="fixed">
      <parent link="base_link"/>
      <child link="hip_link"/>
    </joint>  -->
  <link name="dummy_base_link"/>
  <joint name="dummy_to_base_link" type="fixed">
    <parent link="dummy_base_link"/>
    <child link="base_link"/>
  </joint>
  <joint name="hip_waist_joint" type="revolute">
    <parent link="base_link"/>
    <child link="waist_link"/>
    <origin rpy="0.0 0.0 0.0" xyz="0.0 0.0 0.0722"/>
    <axis xyz="0 0 1"/>
    <limit effort="200.0" lower="-1.2566370614359172" upper="1.2566370614359172" velocity="5.4"/>
    <dynamics damping="1.0" friction="1.0"/>
  </joint>
  <joint name="waist_chest_joint" type="revolute">
    <parent link="waist_link"/>
    <child link="chest_link"/>
    <origin rpy="0.0 0.0 0.0" xyz="0.0 0.0 0.0"/>
    <axis xyz="0 1 0"/>
    <limit effort="200.0" lower="-0.22689280275926285" upper="0.7330382858376184" velocity="5.4"/>
    <dynamics damping="1.0" friction="1.0"/>
  </joint>
  <transmission name="hip_waist_trans">
    <type>transmission_interface/SimpleTransmission</type>
    <joint name="hip_waist_joint">
      <mechanicalReduction>1.0</mechanicalReduction>
      <hardwareInterface>hardware_interface/EffortJointInterface</hardwareInterface>
    </joint>
    <actuator name="hip_motor">
      <mechanicalReduction>1.0</mechanicalReduction>
      <hardwareInterface>hardware_interface/EffortJointInterface</hardwareInterface>
    </actuator>
  </transmission>
  <transmission name="waist_chest_trans">
    <type>transmission_interface/SimpleTransmission</type>
    <joint name="waist_chest_joint">
      <mechanicalReduction>1.0</mechanicalReduction>
      <hardwareInterface>hardware_interface/EffortJointInterface</hardwareInterface>
    </joint>
    <actuator name="waist_motor">
      <hardwareInterface>hardware_interface/EffortJointInterface</hardwareInterface>
      <mechanicalReduction>1.0</mechanicalReduction>
    </actuator>
  </transmission>
  <link name="imu_link">
    <visual>
      <origin rpy="0 0 0" xyz="0 0 0"/>
      <geometry>
        <box size="0.01 0.01 0.01"/>
      </geometry>
    </visual>
    <inertial>
      <mass value="0.01"/>
      <inertia ixx="1e-06" ixy="0" ixz="0" iyy="1e-06" iyz="0" izz="1e-06"/>
      <origin rpy="0 0 0" xyz="0 0 0"/>
    </inertial>
  </link>
  <joint name="imu_joint" type="fixed">
    <origin rpy="3.141592653589793 0.0 1.5707963267948966" xyz="0.04925 0.0 0.078"/>
    <parent link="base_link"/>
    <child link="imu_link"/>
  </joint>
  <gazebo reference="neck_link">
    <mu1>0.9</mu1>
    <mu2>0.9</mu2>
  </gazebo>
  <gazebo reference="updown_head_joint">
    <implicitSpringDamper>1</implicitSpringDamper>
  </gazebo>
  <gazebo reference="neck_link">
    <material>Gazebo/FlatBlack</material>
  </gazebo>
  <gazebo reference="cranium_link">
    <mu1>0.9</mu1>
    <mu2>0.9</mu2>
  </gazebo>
  <gazebo reference="leftright_head_joint">
    <implicitSpringDamper>1</implicitSpringDamper>
  </gazebo>
  <gazebo reference="cranium_link">
    <material>Gazebo/White</material>
  </gazebo>
  <link name="neck_link">
    <visual>
      <origin rpy="0 0 0" xyz="0 0 0"/>
      <geometry>
        <mesh filename="package://talos_description/meshes/head/neck.stl" scale="1 1 1"/>
      </geometry>
      <material name="DarkGrey"/>
    </visual>
    <collision>
      <origin rpy="0 0 0" xyz="0 0 0"/>
      <geometry>
        <mesh filename="package://talos_description/meshes/head/neck_collision.stl" scale="1 1 1"/>
      </geometry>
    </collision>
    <inertial>
      <mass value="0.73746"/>
      <inertia ixx="0.00224878584" ixy="4.69375e-06" ixz="8.55557e-05" iyy="0.00111158492" iyz="-4.132536e-05" izz="0.00205225921"/>
      <origin rpy="0 0 0" xyz="-0.00157211 -0.00157919 0.02175767"/>
    </inertial>
  </link>
  <joint name="updown_head_joint" type="revolute">
    <parent link="chest_link"/>
    <child link="neck_link"/>
    <origin rpy="0.0 0.0 0.0" xyz="0.02000 0.00000 0.32100"/>
    <axis xyz="0 1 0"/>
    <limit effort="8.0" lower="-0.20943951023931956" upper="0.7853981633974483" velocity="3.0"/>
    <dynamics damping="0.5" friction="1.0"/>
  </joint>
  <link name="cranium_link">
    <visual>
      <origin rpy="0 0 0" xyz="0 0 0"/>
      <geometry>
        <mesh filename="package://talos_description/meshes/head/cranium.stl" scale="1 1 1"/>
      </geometry>
      <material name="LightGrey"/>
    </visual>
    <collision>
      <origin rpy="0 0 0" xyz="0 0 0"/>
      <geometry>
        <mesh filename="package://talos_description/meshes/head/cranium_collision.stl" scale="1 1 1"/>
      </geometry>
    </collision>
    <inertial>
      <mass value="1.443954"/>
      <inertia ixx="0.01084624339" ixy="1.050889e-05" ixz="0.00041594252" iyy="0.0109569176" iyz="2.367831e-05" izz="0.00571698895"/>
      <origin rpy="0 0 0" xyz="0.01002657 5.218e-05 0.14136068"/>
    </inertial>
  </link>
  <joint name="leftright_head_joint" type="revolute">
    <parent link="neck_link"/>
    <child link="cranium_link"/>
    <origin rpy="0.0 0.0 0.0" xyz="0.00000 0.00000 0.00000"/>
    <axis xyz="0 0 1"/>
    <limit effort="4.0" lower="-1.3089969389957472" upper="1.3089969389957472" velocity="3.0"/>
    <dynamics damping="0.5" friction="1.0"/>
  </joint>
  <transmission name="updown_head_trans">
    <type>transmission_interface/SimpleTransmission</type>
    <joint name="updown_head_joint">
      <mechanicalReduction>1.0</mechanicalReduction>
      <hardwareInterface>hardware_interface/EffortJointInterface</hardwareInterface>
    </joint>
    <actuator name="neck_motor">
      <hardwareInterface>hardware_interface/EffortJointInterface</hardwareInterface>
      <mechanicalReduction>1.0</mechanicalReduction>
    </actuator>
  </transmission>
  <transmission name="leftright_head_trans">
    <type>transmission_interface/SimpleTransmission</type>
    <joint name="leftright_head_joint">
      <mechanicalReduction>2.0</mechanicalReduction>
      <hardwareInterface>hardware_interface/EffortJointInterface</hardwareInterface>
    </joint>
    <actuator name="cranium_motor">
      <mechanicalReduction>1.0</mechanicalReduction>
      <hardwareInterface>hardware_interface/EffortJointInterface</hardwareInterface>
    </actuator>
  </transmission>
  <link name="rgbd_link">
    <visual>
      <origin rpy="0 0 0" xyz="0 0 0"/>
      <geometry>
        <mesh filename="package://talos_description/meshes/sensors/orbbec/orbbec.STL"/>
      </geometry>
      <material name="DarkGrey">
        <color rgba="0.5 0.5 0.5 1"/>
      </material>
    </visual>
    <collision>
      <origin rpy="0 0 0" xyz="-0.01 0.0025 0"/>
      <geometry>
        <box size="0.04 0.185 0.03"/>
      </geometry>
    </collision>
    <inertial>
      <mass value="0.01"/>
      <inertia ixx="3e-05" ixy="0" ixz="0" iyy="2e-06" iyz="0" izz="3e-05"/>
      <origin rpy="0 0 0" xyz="-0.01 0.0025 0"/>
    </inertial>
  </link>
  <joint name="rgbd_joint" type="fixed">
    <origin rpy="0.0 0.0 0.0" xyz="0.066 0.0 0.1982"/>
    <axis xyz="0 0 1"/>
    <parent link="cranium_link"/>
    <child link="rgbd_link"/>
  </joint>
  <link name="rgbd_optical_frame">
    <inertial>
      <mass value="0.01"/>
      <inertia ixx="0" ixy="0" ixz="0" iyy="0" iyz="0" izz="0"/>
      <origin rpy="0 0 0" xyz="0 0 0"/>
    </inertial>
  </link>
  <joint name="rgbd_optical_joint" type="fixed">
    <origin rpy="-1.5707963267948966 0 -1.5707963267948966" xyz="0 0 0"/>
    <parent link="rgbd_link"/>
    <child link="rgbd_optical_frame"/>
  </joint>
  <gazebo reference="rgbd_link">
    <sensor name="rgbd_frame_sensor" type="depth">
      <always_on>true</always_on>
      <update_rate>30.0</update_rate>
      <camera>
        <horizontal_fov>1.0471975511965976</horizontal_fov>
        <image>
          <format>B8G8R8</format>
          <width>640</width>
          <height>480</height>
        </image>
        <clip>
          <near>0.6</near>
          <far>8.0</far>
        </clip>
      </camera>
      <plugin filename="libgazebo_ros_openni_kinect.so" name="rgbd_frame_controller">
        <alwaysOn>true</alwaysOn>
        <updateRate>30.0</updateRate>
        <cameraName>rgbd</cameraName>
        <imageTopicName>rgb/image_raw</imageTopicName>
        <cameraInfoTopicName>rgb/camera_info</cameraInfoTopicName>
        <depthImageTopicName>depth/image_raw</depthImageTopicName>
        <depthImageCameraInfoTopicName>depth/camera_info</depthImageCameraInfoTopicName>
        <pointCloudTopicName>depth/points</pointCloudTopicName>
        <frameName>rgbd_optical_frame</frameName>
        <pointCloudCutoff>0.45</pointCloudCutoff>
        <rangeMax>10.0</rangeMax>
        <distortionK1>0.00000001</distortionK1>
        <distortionK2>0.00000001</distortionK2>
        <distortionK3>0.00000001</distortionK3>
        <distortionT1>0.00000001</distortionT1>
        <distortionT2>0.00000001</distortionT2>
      </plugin>
    </sensor>
    <sensor name="rgbd_high_res_frame_sensor" type="camera">
      <update_rate>30.0</update_rate>
      <camera name="head">
        <horizontal_fov>1.0471975511965976</horizontal_fov>
        <image>
          <width>1280</width>
          <height>720</height>
          <format>R8G8B8</format>
        </image>
        <clip>
          <near>0.05</near>
          <far>100</far>
        </clip>
        <noise>
          <type>gaussian</type>
          <mean>0.0</mean>
          <stddev>0.007</stddev>
        </noise>
      </camera>
      <plugin filename="libgazebo_ros_camera.so" name="rgbd_high_res_frame_controller">
        <alwaysOn>true</alwaysOn>
        <updateRate>45.0</updateRate>
        <cameraName>rgbd/high_res</cameraName>
        <imageTopicName>/rgbd/rgb/high_res/image_raw</imageTopicName>
        <cameraInfoTopicName>/rgbd/rgb/high_res/camera_info</cameraInfoTopicName>
        <frameName>rgbd_optical_frame</frameName>
        <hackBaseline>0.0</hackBaseline>
        <distortionK1>0.00000001</distortionK1>
        <distortionK2>0.00000001</distortionK2>
        <distortionK3>0.00000001</distortionK3>
        <distortionT1>0.00000001</distortionT1>
        <distortionT2>0.00000001</distortionT2>
      </plugin>
    </sensor>
  </gazebo>
  <gazebo reference="arm_left_1_link">
    <mu1>0.9</mu1>
    <mu2>0.9</mu2>
    <material>Gazebo/FlatBlack</material>
  </gazebo>
  <gazebo reference="arm_left_2_link">
    <mu1>0.9</mu1>
    <mu2>0.9</mu2>
    <material>Gazebo/FlatBlack</material>
  </gazebo>
  <gazebo reference="arm_left_3_link">
    <mu1>0.9</mu1>
    <mu2>0.9</mu2>
    <material>Gazebo/FlatBlack</material>
  </gazebo>
  <gazebo reference="arm_left_4_link">
    <mu1>0.9</mu1>
    <mu2>0.9</mu2>
    <material>Gazebo/FlatBlack</material>
  </gazebo>
  <gazebo reference="arm_left_1_joint">
    <implicitSpringDamper>1</implicitSpringDamper>
  </gazebo>
  <gazebo reference="arm_left_2_joint">
    <implicitSpringDamper>1</implicitSpringDamper>
  </gazebo>
  <gazebo reference="arm_left_3_joint">
    <implicitSpringDamper>1</implicitSpringDamper>
  </gazebo>
  <gazebo reference="arm_left_4_joint">
    <implicitSpringDamper>1</implicitSpringDamper>
  </gazebo>
  <!--************************-->
  <!--        SHOULDER        -->
  <!--************************-->
  <link name="arm_left_1_link">
    <visual>
      <origin rpy="0 0 0" xyz="0 0 0"/>
      <geometry>
        <mesh filename="package://talos_description/meshes/arm/arm_1.STL" scale="1 1 1"/>
      </geometry>
      <material name="DarkGrey"/>
    </visual>
    <collision>
      <origin rpy="0 0 0" xyz="0 0 0"/>
      <geometry>
        <mesh filename="package://talos_description/meshes/arm/arm_1_collision.STL" scale="1 1 1"/>
      </geometry>
    </collision>
    <inertial>
      <mass value="2.714567"/>
      <inertia ixx="0.01237818683" ixy="-3.625571e-05" ixz="7.14472e-05" iyy="0.004191372" iyz="-0.00023639064" izz="0.01358161109"/>
      <origin rpy="0 0 0" xyz="-0.0002762 0.10060223 0.04437419"/>
    </inertial>
  </link>
  <joint name="arm_left_1_joint" type="revolute">
    <parent link="chest_link"/>
    <child link="arm_left_1_link"/>
    <origin rpy="0.0 0.0 0.0" xyz="0.00000 0.1575 0.23200"/>
    <axis xyz="0 0 1"/>
    <limit effort="100.0" lower="-1.5707963267948966" upper="0.7853981633974483" velocity="2.7"/>
    <dynamics damping="1.0" friction="1.0"/>
  </joint>
  <link name="arm_left_2_link">
    <visual>
      <origin rpy="0 0 0" xyz="0 0 0"/>
      <geometry>
        <mesh filename="package://talos_description/meshes/arm/arm_2.STL" scale="1 1 1"/>
      </geometry>
      <material name="DarkGrey"/>
    </visual>
    <collision>
      <origin rpy="0 0 0" xyz="0 0 0"/>
      <geometry>
        <mesh filename="package://talos_description/meshes/arm/arm_2_collision.STL" scale="1 1 1"/>
      </geometry>
    </collision>
    <inertial>
      <mass value="2.425086"/>
      <inertia ixx="0.01297822101" ixy="1.208791e-05" ixz="-0.00320370433" iyy="0.01380870278" iyz="-0.00012770059" izz="0.00478856621"/>
      <origin rpy="0 0 0" xyz="0.01438831 0.00092938 -0.08684268"/>
    </inertial>
  </link>
  <joint name="arm_left_2_joint" type="revolute">
    <parent link="arm_left_1_link"/>
    <child link="arm_left_2_link"/>
    <origin rpy="0.0 0.0 0.0" xyz="0.00493 0.1365 0.04673"/>
    <axis xyz="1 0 0"/>
    <limit effort="100.0" lower="0.008726646259971648" upper="2.871066619530672" velocity="3.66"/>
    <dynamics damping="1.0" friction="1.0"/>
  </joint>
  <link name="arm_left_3_link">
    <visual>
      <origin rpy="0 0 0" xyz="0 0 0"/>
      <geometry>
        <mesh filename="package://talos_description/meshes/arm/arm_3.STL" scale="1 1 1"/>
      </geometry>
      <material name="DarkGrey"/>
    </visual>
    <collision>
      <origin rpy="0 0 0" xyz="0 0 0"/>
      <geometry>
        <mesh filename="package://talos_description/meshes/arm/arm_3_collision.STL" scale="1 1 1"/>
      </geometry>
    </collision>
    <inertial>
      <mass value="2.208741"/>
      <inertia ixx="0.00718831493" ixy="-0.00011563551" ixz="0.00075969733" iyy="0.00693528503" iyz="0.00042134743" izz="0.00388359007"/>
      <origin rpy="0 0 0" xyz="0.0136084 0.01241619 -0.2499004"/>
    </inertial>
  </link>
  <joint name="arm_left_3_joint" type="revolute">
    <parent link="arm_left_2_link"/>
    <child link="arm_left_3_link"/>
    <origin rpy="0.0 0.0 0.0" xyz="0.00000 0.00000 0.00000"/>
    <axis xyz="0 0 1"/>
    <limit effort="70.0" lower="-2.426007660272118" upper="2.426007660272118" velocity="4.58"/>
    <dynamics damping="1.0" friction="1.0"/>
  </joint>
  <!--************************-->
  <!--        ELBOW           -->
  <!--************************-->
  <link name="arm_left_4_link">
    <visual>
      <origin rpy="0 0 0" xyz="0 0 0"/>
      <geometry>
        <mesh filename="package://talos_description/meshes/arm/arm_4.STL" scale="1 1 1"/>
      </geometry>
      <material name="DarkGrey"/>
    </visual>
    <collision>
      <origin rpy="0 0 0" xyz="0 0 0"/>
      <geometry>
        <mesh filename="package://talos_description/meshes/arm/arm_4_collision.STL" scale="1 1 1"/>
      </geometry>
    </collision>
    <inertial>
      <mass value="0.877346"/>
      <inertia ixx="0.00251207716" ixy="0.00010070062" ixz="-0.00032788214" iyy="0.00275869324" iyz="0.00040022227" izz="0.00120735959"/>
      <origin rpy="0 0 0" xyz="-0.00742138 -0.0213895 -0.03312656"/>
    </inertial>
  </link>
  <joint name="arm_left_4_joint" type="revolute">
    <parent link="arm_left_3_link"/>
    <child link="arm_left_4_link"/>
    <origin rpy="0.0 0.0 0.0" xyz="0.02000 0.00000 -0.27300"/>
    <axis xyz="0 1 0"/>
    <limit effort="70.0" lower="-2.234021442552742" upper="-0.003490658503988659" velocity="4.58"/>
    <dynamics damping="1.0" friction="1.0"/>
  </joint>
  <transmission name="arm_left_1_trans">
    <type>transmission_interface/SimpleTransmission</type>
    <actuator name="arm_left_1_motor">
      <mechanicalReduction>1.0</mechanicalReduction>
    </actuator>
    <joint name="arm_left_1_joint">
      <offset>0.0</offset>
      <hardwareInterface>hardware_interface/EffortJointInterface</hardwareInterface>
    </joint>
  </transmission>
  <transmission name="arm_left_2_trans">
    <type>transmission_interface/SimpleTransmission</type>
    <actuator name="arm_left_2_motor">
      <mechanicalReduction>1.0</mechanicalReduction>
    </actuator>
    <joint name="arm_left_2_joint">
      <offset>0.0</offset>
      <hardwareInterface>hardware_interface/EffortJointInterface</hardwareInterface>
    </joint>
  </transmission>
  <transmission name="arm_left_3_trans">
    <type>transmission_interface/SimpleTransmission</type>
    <actuator name="arm_left_3_motor">
      <mechanicalReduction>1.0</mechanicalReduction>
    </actuator>
    <joint name="arm_left_3_joint">
      <offset>0.0</offset>
      <hardwareInterface>hardware_interface/EffortJointInterface</hardwareInterface>
    </joint>
  </transmission>
  <transmission name="arm_left_4_trans">
    <type>transmission_interface/SimpleTransmission</type>
    <actuator name="arm_left_4_motor">
      <mechanicalReduction>1.0</mechanicalReduction>
    </actuator>
    <joint name="arm_left_4_joint">
      <offset>0.0</offset>
      <hardwareInterface>hardware_interface/EffortJointInterface</hardwareInterface>
    </joint>
  </transmission>
  <!--************************-->
  <!--        WRIST           -->
  <!--************************-->
  <link name="arm_left_5_link">
    <visual>
      <origin rpy="0 0 0" xyz="0 0 0"/>
      <geometry>
        <mesh filename="package://talos_description/meshes/arm/arm_5.STL" scale="1 1 1"/>
      </geometry>
      <material name="LightGrey"/>
    </visual>
    <collision>
      <origin rpy="0 0 0" xyz="0 0 0"/>
      <geometry>
        <mesh filename="package://talos_description/meshes/arm/arm_5_collision.STL" scale="1 1 1"/>
      </geometry>
    </collision>
    <inertial>
      <mass value="1.877923"/>
      <inertia ixx="0.00349507283" ixy="1.265489e-05" ixz="1.038286e-05" iyy="0.00436830072" iyz="-9.736042e-05" izz="0.0022826337"/>
      <origin rpy="0 0 0" xyz="-6e-05 0.003262 0.079625"/>
    </inertial>
  </link>
  <joint name="arm_left_5_joint" type="revolute">
    <parent link="arm_left_4_link"/>
    <child link="arm_left_5_link"/>
    <origin rpy="0.0 0.0 0.0" xyz="-0.02000 0.00000 -0.26430"/>
    <axis xyz="0 0 1"/>
    <limit effort="20.0" lower="-2.5132741228718345" upper="2.5132741228718345" velocity="1.95"/>
    <dynamics damping="1.0" friction="1.0"/>
  </joint>
  <link name="arm_left_6_link">
    <visual>
      <origin rpy="0 0 0" xyz="0 0 0"/>
      <geometry>
        <mesh filename="package://talos_description/meshes/arm/arm_6.STL" scale="1 1 1"/>
      </geometry>
      <material name="LightGrey"/>
    </visual>
    <collision>
      <origin rpy="0 0 0" xyz="0 0 0"/>
      <geometry>
        <mesh filename="package://talos_description/meshes/arm/arm_6_collision.STL" scale="1 1 1"/>
      </geometry>
    </collision>
    <inertial>
      <mass value="0.40931"/>
      <inertia ixx="0.00010700023" ixy="-8.899e-08" ixz="-4.392e-08" iyy="0.00014101316" iyz="4.1702e-07" izz="0.00015398658"/>
      <origin rpy="0 0 0" xyz="2.1e-05 -0.001965 -0.000591"/>
    </inertial>
  </link>
  <joint name="arm_left_6_joint" type="revolute">
    <parent link="arm_left_5_link"/>
    <child link="arm_left_6_link"/>
    <origin rpy="0.0 0.0 0.0" xyz="0.00000 0.00000 0.00000"/>
    <axis xyz="1 0 0"/>
    <limit effort="8.0" lower="-1.3700834628155487" upper="1.3700834628155487" velocity="1.76"/>
    <dynamics damping="1.0" friction="1.0"/>
  </joint>
  <link name="arm_left_7_link">
    <visual>
      <origin rpy="0 0 0" xyz="0 0 0"/>
      <geometry>
        <mesh filename="package://talos_description/meshes/arm/arm_7.STL" scale="1 1 1"/>
      </geometry>
      <material name="DarkGrey"/>
    </visual>
    <collision>
      <origin rpy="0 0 0" xyz="0 0 0"/>
      <geometry>
        <mesh filename="package://talos_description/meshes/arm/arm_7_collision.STL" scale="1 1 1"/>
      </geometry>
    </collision>
    <inertial>
      <mass value="0.308441"/>
      <inertia ixx="0.00030894317" ixy="-1.58687e-06" ixz="1.73418e-06" iyy="0.00021886181" iyz="-1.221167e-05" izz="0.00017519492"/>
      <origin rpy="0 0 0" xyz="0.007525 0.001378 -0.02463"/>
    </inertial>
  </link>
  <joint name="arm_left_7_joint" type="revolute">
    <parent link="arm_left_6_link"/>
    <child link="arm_left_7_link"/>
    <origin rpy="0.0 0.0 0.0" xyz="0.0 0.0 0.0"/>
    <axis xyz="0 1 0"/>
    <limit effort="8.0" lower="-0.6806784082777885" upper="0.6806784082777885" velocity="1.76"/>
    <dynamics damping="1.0" friction="1.0"/>
  </joint>
  <transmission name="arm_left_5_trans">
    <type>transmission_interface/SimpleTransmission</type>
    <actuator name="arm_left_5_motor">
      <mechanicalReduction>1.0</mechanicalReduction>
    </actuator>
    <joint name="arm_left_5_joint">
      <offset>0.0</offset>
      <!-- <hardwareInterface>hardware_interface/PositionJointInterface</hardwareInterface> -->
      <hardwareInterface>hardware_interface/EffortJointInterface</hardwareInterface>
    </joint>
  </transmission>
  <transmission name="wrist_left_6_trans">
    <type>transmission_interface/SimpleTransmission</type>
    <joint name="arm_left_6_joint">
      <mechanicalReduction>-1.0</mechanicalReduction>
      <hardwareInterface>hardware_interface/EffortJointInterface</hardwareInterface>
    </joint>
    <actuator name="arm_left_6_motor">
      <mechanicalReduction>-1.0</mechanicalReduction>
      <hardwareInterface>hardware_interface/EffortJointInterface</hardwareInterface>
    </actuator>
  </transmission>
  <transmission name="wrist_left_7_trans">
    <type>transmission_interface/SimpleTransmission</type>
    <joint name="arm_left_7_joint">
      <mechanicalReduction>-1.0</mechanicalReduction>
      <hardwareInterface>hardware_interface/EffortJointInterface</hardwareInterface>
    </joint>
    <actuator name="arm_left_7_motor">
      <mechanicalReduction>1.0</mechanicalReduction>
      <hardwareInterface>hardware_interface/EffortJointInterface</hardwareInterface>
    </actuator>
  </transmission>
  <gazebo reference="arm_right_1_link">
    <mu1>0.9</mu1>
    <mu2>0.9</mu2>
    <material>Gazebo/FlatBlack</material>
  </gazebo>
  <gazebo reference="arm_right_2_link">
    <mu1>0.9</mu1>
    <mu2>0.9</mu2>
    <material>Gazebo/FlatBlack</material>
  </gazebo>
  <gazebo reference="arm_right_3_link">
    <mu1>0.9</mu1>
    <mu2>0.9</mu2>
    <material>Gazebo/FlatBlack</material>
  </gazebo>
  <gazebo reference="arm_right_4_link">
    <mu1>0.9</mu1>
    <mu2>0.9</mu2>
    <material>Gazebo/FlatBlack</material>
  </gazebo>
  <gazebo reference="arm_right_1_joint">
    <implicitSpringDamper>1</implicitSpringDamper>
  </gazebo>
  <gazebo reference="arm_right_2_joint">
    <implicitSpringDamper>1</implicitSpringDamper>
  </gazebo>
  <gazebo reference="arm_right_3_joint">
    <implicitSpringDamper>1</implicitSpringDamper>
  </gazebo>
  <gazebo reference="arm_right_4_joint">
    <implicitSpringDamper>1</implicitSpringDamper>
  </gazebo>
  <!--************************-->
  <!--        SHOULDER        -->
  <!--************************-->
  <link name="arm_right_1_link">
    <visual>
      <origin rpy="0 0 0" xyz="0 0 0"/>
      <geometry>
        <mesh filename="package://talos_description/meshes/arm/arm_1.STL" scale="1 -1 1"/>
      </geometry>
      <material name="DarkGrey"/>
    </visual>
    <collision>
      <origin rpy="0 0 0" xyz="0 0 0"/>
      <geometry>
        <mesh filename="package://talos_description/meshes/arm/arm_1_collision.STL" scale="1 -1 1"/>
      </geometry>
    </collision>
    <inertial>
      <mass value="2.714567"/>
      <inertia ixx="0.01237818683" ixy="-3.625571e-05" ixz="7.14472e-05" iyy="0.004191372" iyz="-0.00023639064" izz="0.01358161109"/>
      <origin rpy="0 0 0" xyz="-0.0002762 0.10060223 0.04437419"/>
    </inertial>
  </link>
  <joint name="arm_right_1_joint" type="revolute">
    <parent link="chest_link"/>
    <child link="arm_right_1_link"/>
    <origin rpy="0.0 0.0 0.0" xyz="0.00000 -0.1575 0.23200"/>
    <axis xyz="0 0 1"/>
    <limit effort="100.0" lower="-0.7853981633974483" upper="1.5707963267948966" velocity="2.7"/>
    <dynamics damping="1.0" friction="1.0"/>
  </joint>
  <link name="arm_right_2_link">
    <visual>
      <origin rpy="0 0 0" xyz="0 0 0"/>
      <geometry>
        <mesh filename="package://talos_description/meshes/arm/arm_2.STL" scale="1 -1 1"/>
      </geometry>
      <material name="DarkGrey"/>
    </visual>
    <collision>
      <origin rpy="0 0 0" xyz="0 0 0"/>
      <geometry>
        <mesh filename="package://talos_description/meshes/arm/arm_2_collision.STL" scale="1 -1 1"/>
      </geometry>
    </collision>
    <inertial>
      <mass value="2.425086"/>
      <inertia ixx="0.01297822101" ixy="1.208791e-05" ixz="-0.00320370433" iyy="0.01380870278" iyz="-0.00012770059" izz="0.00478856621"/>
      <origin rpy="0 0 0" xyz="0.01438831 0.00092938 -0.08684268"/>
    </inertial>
  </link>
  <joint name="arm_right_2_joint" type="revolute">
    <parent link="arm_right_1_link"/>
    <child link="arm_right_2_link"/>
    <origin rpy="0.0 0.0 0.0" xyz="0.00493 -0.1365 0.04673"/>
    <axis xyz="1 0 0"/>
    <limit effort="100.0" lower="-2.871066619530672" upper="-0.008726646259971648" velocity="3.66"/>
    <dynamics damping="1.0" friction="1.0"/>
  </joint>
  <link name="arm_right_3_link">
    <visual>
      <origin rpy="0 0 0" xyz="0 0 0"/>
      <geometry>
        <mesh filename="package://talos_description/meshes/arm/arm_3.STL" scale="1 -1 1"/>
      </geometry>
      <material name="DarkGrey"/>
    </visual>
    <collision>
      <origin rpy="0 0 0" xyz="0 0 0"/>
      <geometry>
        <mesh filename="package://talos_description/meshes/arm/arm_3_collision.STL" scale="1 -1 1"/>
      </geometry>
    </collision>
    <inertial>
      <mass value="2.208741"/>
      <inertia ixx="0.00718831493" ixy="-0.00011563551" ixz="0.00075969733" iyy="0.00693528503" iyz="0.00042134743" izz="0.00388359007"/>
      <origin rpy="0 0 0" xyz="0.0136084 0.01241619 -0.2499004"/>
    </inertial>
  </link>
  <joint name="arm_right_3_joint" type="revolute">
    <parent link="arm_right_2_link"/>
    <child link="arm_right_3_link"/>
    <origin rpy="0.0 0.0 0.0" xyz="0.00000 0.00000 0.00000"/>
    <axis xyz="0 0 1"/>
    <limit effort="70.0" lower="-2.426007660272118" upper="2.426007660272118" velocity="4.58"/>
    <dynamics damping="1.0" friction="1.0"/>
  </joint>
  <!--************************-->
  <!--        ELBOW           -->
  <!--************************-->
  <link name="arm_right_4_link">
    <visual>
      <origin rpy="0 0 0" xyz="0 0 0"/>
      <geometry>
        <mesh filename="package://talos_description/meshes/arm/arm_4.STL" scale="1 -1 1"/>
      </geometry>
      <material name="DarkGrey"/>
    </visual>
    <collision>
      <origin rpy="0 0 0" xyz="0 0 0"/>
      <geometry>
        <mesh filename="package://talos_description/meshes/arm/arm_4_collision.STL" scale="1 -1 1"/>
      </geometry>
    </collision>
    <inertial>
      <mass value="0.877346"/>
      <inertia ixx="0.00251207716" ixy="0.00010070062" ixz="-0.00032788214" iyy="0.00275869324" iyz="0.00040022227" izz="0.00120735959"/>
      <origin rpy="0 0 0" xyz="-0.00742138 -0.0213895 -0.03312656"/>
    </inertial>
  </link>
  <joint name="arm_right_4_joint" type="revolute">
    <parent link="arm_right_3_link"/>
    <child link="arm_right_4_link"/>
    <origin rpy="0.0 0.0 0.0" xyz="0.02000 0.00000 -0.27300"/>
    <axis xyz="0 1 0"/>
    <limit effort="70.0" lower="-2.234021442552742" upper="-0.003490658503988659" velocity="4.58"/>
    <dynamics damping="1.0" friction="1.0"/>
  </joint>
  <transmission name="arm_right_1_trans">
    <type>transmission_interface/SimpleTransmission</type>
    <actuator name="arm_right_1_motor">
      <mechanicalReduction>1.0</mechanicalReduction>
    </actuator>
    <joint name="arm_right_1_joint">
      <offset>0.0</offset>
      <hardwareInterface>hardware_interface/EffortJointInterface</hardwareInterface>
    </joint>
  </transmission>
  <transmission name="arm_right_2_trans">
    <type>transmission_interface/SimpleTransmission</type>
    <actuator name="arm_right_2_motor">
      <mechanicalReduction>1.0</mechanicalReduction>
    </actuator>
    <joint name="arm_right_2_joint">
      <offset>0.0</offset>
      <hardwareInterface>hardware_interface/EffortJointInterface</hardwareInterface>
    </joint>
  </transmission>
  <transmission name="arm_right_3_trans">
    <type>transmission_interface/SimpleTransmission</type>
    <actuator name="arm_right_3_motor">
      <mechanicalReduction>1.0</mechanicalReduction>
    </actuator>
    <joint name="arm_right_3_joint">
      <offset>0.0</offset>
      <hardwareInterface>hardware_interface/EffortJointInterface</hardwareInterface>
    </joint>
  </transmission>
  <transmission name="arm_right_4_trans">
    <type>transmission_interface/SimpleTransmission</type>
    <actuator name="arm_right_4_motor">
      <mechanicalReduction>1.0</mechanicalReduction>
    </actuator>
    <joint name="arm_right_4_joint">
      <offset>0.0</offset>
      <hardwareInterface>hardware_interface/EffortJointInterface</hardwareInterface>
    </joint>
  </transmission>
  <!--************************-->
  <!--        WRIST           -->
  <!--************************-->
  <link name="arm_right_5_link">
    <visual>
      <origin rpy="0 0 0" xyz="0 0 0"/>
      <geometry>
        <mesh filename="package://talos_description/meshes/arm/arm_5.STL" scale="1 -1 1"/>
      </geometry>
      <material name="LightGrey"/>
    </visual>
    <collision>
      <origin rpy="0 0 0" xyz="0 0 0"/>
      <geometry>
        <mesh filename="package://talos_description/meshes/arm/arm_5_collision.STL" scale="1 -1 1"/>
      </geometry>
    </collision>
    <inertial>
      <mass value="1.877923"/>
      <inertia ixx="0.00349507283" ixy="1.265489e-05" ixz="1.038286e-05" iyy="0.00436830072" iyz="-9.736042e-05" izz="0.0022826337"/>
      <origin rpy="0 0 0" xyz="-6e-05 0.003262 0.079625"/>
    </inertial>
  </link>
  <joint name="arm_right_5_joint" type="revolute">
    <parent link="arm_right_4_link"/>
    <child link="arm_right_5_link"/>
    <origin rpy="0.0 0.0 0.0" xyz="-0.02000 0.00000 -0.26430"/>
    <axis xyz="0 0 1"/>
    <limit effort="20.0" lower="-2.5132741228718345" upper="2.5132741228718345" velocity="1.95"/>
    <dynamics damping="1.0" friction="1.0"/>
  </joint>
  <link name="arm_right_6_link">
    <visual>
      <origin rpy="0 0 0" xyz="0 0 0"/>
      <geometry>
        <mesh filename="package://talos_description/meshes/arm/arm_6.STL" scale="1 -1 1"/>
      </geometry>
      <material name="LightGrey"/>
    </visual>
    <collision>
      <origin rpy="0 0 0" xyz="0 0 0"/>
      <geometry>
        <mesh filename="package://talos_description/meshes/arm/arm_6_collision.STL" scale="1 -1 1"/>
      </geometry>
    </collision>
    <inertial>
      <mass value="0.40931"/>
      <inertia ixx="0.00010700023" ixy="-8.899e-08" ixz="-4.392e-08" iyy="0.00014101316" iyz="4.1702e-07" izz="0.00015398658"/>
      <origin rpy="0 0 0" xyz="2.1e-05 -0.001965 -0.000591"/>
    </inertial>
  </link>
  <joint name="arm_right_6_joint" type="revolute">
    <parent link="arm_right_5_link"/>
    <child link="arm_right_6_link"/>
    <origin rpy="0.0 0.0 0.0" xyz="0.00000 0.00000 0.00000"/>
    <axis xyz="1 0 0"/>
    <limit effort="8.0" lower="-1.3700834628155487" upper="1.3700834628155487" velocity="1.76"/>
    <dynamics damping="1.0" friction="1.0"/>
  </joint>
  <link name="arm_right_7_link">
    <visual>
      <origin rpy="0 0 0" xyz="0 0 0"/>
      <geometry>
        <mesh filename="package://talos_description/meshes/arm/arm_7.STL" scale="1 -1 1"/>
      </geometry>
      <material name="DarkGrey"/>
    </visual>
    <collision>
      <origin rpy="0 0 0" xyz="0 0 0"/>
      <geometry>
        <mesh filename="package://talos_description/meshes/arm/arm_7_collision.STL" scale="1 -1 1"/>
      </geometry>
    </collision>
    <inertial>
      <mass value="0.308441"/>
      <inertia ixx="0.00030894317" ixy="-1.58687e-06" ixz="1.73418e-06" iyy="0.00021886181" iyz="-1.221167e-05" izz="0.00017519492"/>
      <origin rpy="0 0 0" xyz="0.007525 0.001378 -0.02463"/>
    </inertial>
  </link>
  <joint name="arm_right_7_joint" type="revolute">
    <parent link="arm_right_6_link"/>
    <child link="arm_right_7_link"/>
    <origin rpy="0.0 0.0 0.0" xyz="0.0 0.0 0.0"/>
    <axis xyz="0 1 0"/>
    <limit effort="8.0" lower="-0.6806784082777885" upper="0.6806784082777885" velocity="1.76"/>
    <dynamics damping="1.0" friction="1.0"/>
  </joint>
  <transmission name="arm_right_5_trans">
    <type>transmission_interface/SimpleTransmission</type>
    <actuator name="arm_right_5_motor">
      <mechanicalReduction>1.0</mechanicalReduction>
    </actuator>
    <joint name="arm_right_5_joint">
      <offset>0.0</offset>
      <!-- <hardwareInterface>hardware_interface/PositionJointInterface</hardwareInterface> -->
      <hardwareInterface>hardware_interface/EffortJointInterface</hardwareInterface>
    </joint>
  </transmission>
  <transmission name="wrist_right_6_trans">
    <type>transmission_interface/SimpleTransmission</type>
    <joint name="arm_right_6_joint">
      <mechanicalReduction>-1.0</mechanicalReduction>
      <hardwareInterface>hardware_interface/EffortJointInterface</hardwareInterface>
    </joint>
    <actuator name="arm_right_6_motor">
      <mechanicalReduction>-1.0</mechanicalReduction>
      <hardwareInterface>hardware_interface/EffortJointInterface</hardwareInterface>
    </actuator>
  </transmission>
  <transmission name="wrist_right_7_trans">
    <type>transmission_interface/SimpleTransmission</type>
    <joint name="arm_right_7_joint">
      <mechanicalReduction>-1.0</mechanicalReduction>
      <hardwareInterface>hardware_interface/EffortJointInterface</hardwareInterface>
    </joint>
    <actuator name="arm_right_7_motor">
      <mechanicalReduction>1.0</mechanicalReduction>
      <hardwareInterface>hardware_interface/EffortJointInterface</hardwareInterface>
    </actuator>
  </transmission>
  <!--************************-->
  <!--        ft sensor       -->
  <!--************************-->
  <link name="wrist_right_ft_link">
    <visual>
      <origin rpy="0 0 0" xyz="0 0 0"/>
      <geometry>
        <cylinder length="0.0157" radius="0.0225"/>
      </geometry>
      <material name="LightGrey"/>
    </visual>
    <collision>
      <origin rpy="0 0 0" xyz="0 0 0"/>
      <geometry>
        <cylinder length="0.0157" radius="0.0225"/>
      </geometry>
    </collision>
    <inertial>
      <mass value="0.095"/>
      <inertia ixx="1.108502e-05" ixy="9.9077e-07" ixz="-2.3811e-07" iyy="1.092725e-05" iyz="2.3137e-07" izz="1.898772e-05"/>
      <origin rpy="0 0 0" xyz="-0.001001 0.000995 -0.008108"/>
    </inertial>
  </link>
  <joint name="wrist_right_ft_joint" type="fixed">
    <parent link="arm_right_7_link"/>
    <child link="wrist_right_ft_link"/>
    <origin rpy="0.0 0 -1.5707963267948966" xyz="0 0 -0.051"/>
  </joint>
  <!--***********************-->
  <!--       FT TOOL         -->
  <!--***********************-->
  <link name="wrist_right_ft_tool_link">
    <visual>
      <origin rpy="0 0.0 0" xyz="0.0 0 0"/>
      <geometry>
        <cylinder length="0.00975" radius="0.025"/>
      </geometry>
      <material name="FlatBlack"/>
    </visual>
    <collision>
      <origin rpy="0 0.0 0" xyz="0.0 0 0"/>
      <geometry>
        <cylinder length="0.00975" radius="0.025"/>
      </geometry>
    </collision>
    <inertial>
      <mass value="0.001"/>
      <inertia ixx="0" ixy="0" ixz="0" iyy="0" iyz="0" izz="0"/>
      <origin rpy="0 0 0" xyz="0 0 0"/>
    </inertial>
  </link>
  <joint name="wrist_right_tool_joint" type="fixed">
    <parent link="wrist_right_ft_link"/>
    <child link="wrist_right_ft_tool_link"/>
    <origin rpy="0 0 -1.5707963267948966" xyz="0 0 -0.012725"/>
  </joint>
  <!--************************-->
  <!--        ft sensor       -->
  <!--************************-->
  <link name="wrist_left_ft_link">
    <visual>
      <origin rpy="0 0 0" xyz="0 0 0"/>
      <geometry>
        <cylinder length="0.0157" radius="0.0225"/>
      </geometry>
      <material name="LightGrey"/>
    </visual>
    <collision>
      <origin rpy="0 0 0" xyz="0 0 0"/>
      <geometry>
        <cylinder length="0.0157" radius="0.0225"/>
      </geometry>
    </collision>
    <inertial>
      <mass value="0.095"/>
      <inertia ixx="1.108502e-05" ixy="9.9077e-07" ixz="-2.3811e-07" iyy="1.092725e-05" iyz="2.3137e-07" izz="1.898772e-05"/>
      <origin rpy="0 0 0" xyz="-0.001001 0.000995 -0.008108"/>
    </inertial>
  </link>
  <joint name="wrist_left_ft_joint" type="fixed">
    <parent link="arm_left_7_link"/>
    <child link="wrist_left_ft_link"/>
    <origin rpy="0.0 0 -4.71238898038469" xyz="0 0 -0.051"/>
  </joint>
  <!--***********************-->
  <!--       FT TOOL         -->
  <!--***********************-->
  <link name="wrist_left_ft_tool_link">
    <visual>
      <origin rpy="0 0.0 0" xyz="0.0 0 0"/>
      <geometry>
        <cylinder length="0.00975" radius="0.025"/>
      </geometry>
      <material name="FlatBlack"/>
    </visual>
    <collision>
      <origin rpy="0 0.0 0" xyz="0.0 0 0"/>
      <geometry>
        <cylinder length="0.00975" radius="0.025"/>
      </geometry>
    </collision>
    <inertial>
      <mass value="0.001"/>
      <inertia ixx="0" ixy="0" ixz="0" iyy="0" iyz="0" izz="0"/>
      <origin rpy="0 0 0" xyz="0 0 0"/>
    </inertial>
  </link>
  <joint name="wrist_left_tool_joint" type="fixed">
    <parent link="wrist_left_ft_link"/>
    <child link="wrist_left_ft_tool_link"/>
    <origin rpy="0 0 4.71238898038469" xyz="0 0 -0.012725"/>
  </joint>
  <gazebo>
    <plugin filename="libroboticsgroup_upatras_gazebo_mimic_joint_plugin.so" name="mimic_gripper_left_inner_double_joint">
      <joint>gripper_left_joint</joint>
      <mimicJoint>gripper_left_inner_double_joint</mimicJoint>
      <multiplier>1.0</multiplier>
      <offset>0.0</offset>
      <hasPID/>
    </plugin>
    <plugin filename="libroboticsgroup_upatras_gazebo_mimic_joint_plugin.so" name="mimic_gripper_left_fingertip_1_joint">
      <joint>gripper_left_joint</joint>
      <mimicJoint>gripper_left_fingertip_1_joint</mimicJoint>
      <multiplier>-1.0</multiplier>
      <offset>0.0</offset>
      <hasPID/>
    </plugin>
    <plugin filename="libroboticsgroup_upatras_gazebo_mimic_joint_plugin.so" name="mimic_gripper_left_fingertip_2_joint">
      <joint>gripper_left_joint</joint>
      <mimicJoint>gripper_left_fingertip_2_joint</mimicJoint>
      <multiplier>-1.0</multiplier>
      <offset>0.0</offset>
      <hasPID/>
    </plugin>
    <plugin filename="libroboticsgroup_upatras_gazebo_mimic_joint_plugin.so" name="mimic_gripper_left_inner_single_joint">
      <joint>gripper_left_joint</joint>
      <mimicJoint>gripper_left_inner_single_joint</mimicJoint>
      <multiplier>-1.0</multiplier>
      <offset>0.0</offset>
      <hasPID/>
    </plugin>
    <plugin filename="libroboticsgroup_upatras_gazebo_mimic_joint_plugin.so" name="mimic_gripper_left_motor_single_joint">
      <joint>gripper_left_joint</joint>
      <mimicJoint>gripper_left_motor_single_joint</mimicJoint>
      <multiplier>-1.0</multiplier>
      <offset>0.0</offset>
      <hasPID/>
    </plugin>
    <plugin filename="libroboticsgroup_upatras_gazebo_mimic_joint_plugin.so" name="mimic_gripper_left_fingertip_3_joint">
      <joint>gripper_left_joint</joint>
      <mimicJoint>gripper_left_fingertip_3_joint</mimicJoint>
      <multiplier>-1.0</multiplier>
      <offset>0.0</offset>
      <hasPID/>
    </plugin>
  </gazebo>
  <gazebo reference="gripper_left_joint">
    <implicitSpringDamper>1</implicitSpringDamper>
    <provideFeedback>1</provideFeedback>
  </gazebo>
  <gazebo reference="gripper_left_inner_double_joint">
    <implicitSpringDamper>1</implicitSpringDamper>
    <provideFeedback>1</provideFeedback>
  </gazebo>
  <gazebo reference="gripper_left_fingertip_1_joint">
    <implicitSpringDamper>1</implicitSpringDamper>
    <provideFeedback>1</provideFeedback>
  </gazebo>
  <gazebo reference="gripper_left_fingertip_2_joint">
    <implicitSpringDamper>1</implicitSpringDamper>
    <provideFeedback>1</provideFeedback>
  </gazebo>
  <gazebo reference="gripper_left_motor_single_joint">
    <implicitSpringDamper>1</implicitSpringDamper>
    <provideFeedback>1</provideFeedback>
  </gazebo>
  <gazebo reference="gripper_left_fingertip_3_joint">
    <implicitSpringDamper>1</implicitSpringDamper>
    <provideFeedback>1</provideFeedback>
  </gazebo>
  <gazebo reference="gripper_left_base_link">
    <material>Gazebo/FlatBlack</material>
  </gazebo>
  <gazebo reference="gripper_left_motor_double_link">
    <material>Gazebo/Orange</material>
  </gazebo>
  <gazebo reference="gripper_left_inner_double_link">
    <material>Gazebo/Orange</material>
  </gazebo>
  <gazebo reference="gripper_left_fingertip_1_link">
    <material>Gazebo/FlatBlack</material>
  </gazebo>
  <gazebo reference="gripper_left_motor_single_link">
    <material>Gazebo/Orange</material>
  </gazebo>
  <gazebo reference="gripper_left_inner_single_link">
    <material>Gazebo/Orange</material>
  </gazebo>
  <gazebo reference="gripper_left_fingertip_2_link">
    <material>Gazebo/FlatBlack</material>
  </gazebo>
  <gazebo reference="gripper_left_fingertip_3_link">
    <material>Gazebo/FlatBlack</material>
  </gazebo>
  <link name="gripper_left_base_link">
    <visual>
      <origin rpy="0 0 0" xyz="0 0 0"/>
      <geometry>
        <mesh filename="package://talos_description/meshes/gripper/base_link.STL" scale="1 1 1"/>
      </geometry>
      <material name="DarkGrey"/>
    </visual>
    <collision>
      <origin rpy="0 0 0" xyz="0 0 0"/>
      <geometry>
        <mesh filename="package://talos_description/meshes/gripper/base_link_collision.STL" scale="1 1 1"/>
      </geometry>
    </collision>
    <inertial>
      <mass value="0.637534"/>
      <inertia ixx="0.0005849692" ixy="4.37159e-06" ixz="-1.2589e-05" iyy="0.00067076439" iyz="2.824361e-05" izz="0.00085526645"/>
      <origin rpy="0 0 0" xyz="2.8e-05 0.005394 -0.023654"/>
    </inertial>
  </link>
  <joint name="gripper_left_base_link_joint" type="fixed">
    <parent link="wrist_left_ft_tool_link"/>
    <child link="gripper_left_base_link"/>
    <origin rpy="0.0 0.0 0.0" xyz="0.00000 0.00000 -0.02875"/>
    <axis xyz="0 0 0"/>
  </joint>
  <link name="gripper_left_motor_double_link">
    <visual>
      <origin rpy="0 0 0" xyz="0 0 0"/>
      <geometry>
        <mesh filename="package://talos_description/meshes/gripper/gripper_motor_double.STL" scale="1 1 1"/>
      </geometry>
      <material name="Orange"/>
    </visual>
    <collision>
      <origin rpy="0 0 0" xyz="0 0 0"/>
      <geometry>
        <mesh filename="package://talos_description/meshes/gripper/gripper_motor_double_collision.STL" scale="1 1 1"/>
      </geometry>
    </collision>
    <inertial>
      <mass value="0.134356"/>
      <inertia ixx="0.00013479919" ixy="6.184429e-05" ixz="-3.0798e-05" iyy="0.00019602207" iyz="4.707722e-05" izz="0.00024217879"/>
      <origin rpy="0 0 0" xyz="0.019654 0.018572 -0.011998"/>
    </inertial>
  </link>
  <joint name="gripper_left_joint" type="revolute">
    <parent link="gripper_left_base_link"/>
    <child link="gripper_left_motor_double_link"/>
    <origin rpy="0.0 0.0 0.0" xyz="0.0 0.02025 -0.03"/>
    <axis xyz="1 0 0"/>
    <limit effort="1.0" lower="-0.9599310885968813" upper="0.0" velocity="1.0"/>
    <dynamics damping="1.0" friction="1.0"/>
  </joint>
  <link name="gripper_left_inner_double_link">
    <visual>
      <origin rpy="0 0 0" xyz="0 0 0"/>
      <geometry>
        <mesh filename="package://talos_description/meshes/gripper/inner_double.STL" scale="1 1 1"/>
      </geometry>
      <material name="Orange"/>
    </visual>
    <collision>
      <origin rpy="0 0 0" xyz="0 0 0"/>
      <geometry>
        <mesh filename="package://talos_description/meshes/gripper/inner_double_collision.STL" scale="1 1 1"/>
      </geometry>
    </collision>
    <inertial>
      <mass value="0.087986"/>
      <inertia ixx="7.410642e-05" ixy="-7.4773e-07" ixz="1.01536e-06" iyy="0.0001279418" iyz="2.504083e-05" izz="0.00010495175"/>
      <origin rpy="0 0 0" xyz="-0.013283 0.036852 -0.023153"/>
    </inertial>
  </link>
  <joint name="gripper_left_inner_double_joint" type="revolute">
    <parent link="gripper_left_base_link"/>
    <child link="gripper_left_inner_double_link"/>
    <origin rpy="0.0 0.0 0.0" xyz="0.00000 0.00525 -0.05598"/>
    <axis xyz="1 0 0"/>
    <limit effort="100.0" lower="-1.0471975511965976" upper="0.0" velocity="1.0"/>
    <mimic joint="gripper_left_joint" multiplier="1.0" offset="0.0"/>
  </joint>
  <link name="gripper_left_fingertip_1_link">
    <visual>
      <origin rpy="0 0 0" xyz="0 0 0"/>
      <geometry>
        <mesh filename="package://talos_description/meshes/gripper/fingertip.STL" scale="1 1 1"/>
      </geometry>
      <material name="DarkGrey"/>
    </visual>
    <collision>
      <origin rpy="0 0 0" xyz="0 0 0"/>
      <geometry>
        <mesh filename="package://talos_description/meshes/gripper/fingertip_collision.STL" scale="1 1 1"/>
      </geometry>
    </collision>
    <inertial>
      <mass value="0.026301"/>
      <inertia ixx="8e-06" ixy="0" ixz="0" iyy="8.69179e-06" iyz="-1.43612e-06" izz="2.3082e-06"/>
      <origin rpy="0 0 0" xyz="0 0.004604 -0.002537"/>
    </inertial>
  </link>
  <joint name="gripper_left_fingertip_1_joint" type="revolute">
    <parent link="gripper_left_inner_double_link"/>
    <child link="gripper_left_fingertip_1_link"/>
    <origin rpy="0.0 0.0 0.0" xyz="0.03200 0.04589 -0.06553"/>
    <axis xyz="1 0 0"/>
    <limit effort="100.0" lower="0.0" upper="1.0471975511965976" velocity="1.0"/>
    <mimic joint="gripper_left_joint" multiplier="-1.0" offset="0.0"/>
  </joint>
  <link name="gripper_left_fingertip_2_link">
    <visual>
      <origin rpy="0 0 0" xyz="0 0 0"/>
      <geometry>
        <mesh filename="package://talos_description/meshes/gripper/fingertip.STL" scale="1 1 1"/>
      </geometry>
      <material name="DarkGrey"/>
    </visual>
    <collision>
      <origin rpy="0 0 0" xyz="0 0 0"/>
      <geometry>
        <mesh filename="package://talos_description/meshes/gripper/fingertip_collision.STL" scale="1 1 1"/>
      </geometry>
    </collision>
    <inertial>
      <mass value="0.026301"/>
      <inertia ixx="8e-06" ixy="0" ixz="0" iyy="8.69179e-06" iyz="-1.43612e-06" izz="2.3082e-06"/>
      <origin rpy="0 0 0" xyz="0 0.004604 -0.002537"/>
    </inertial>
  </link>
  <joint name="gripper_left_fingertip_2_joint" type="revolute">
    <parent link="gripper_left_inner_double_link"/>
    <child link="gripper_left_fingertip_2_link"/>
    <origin rpy="0.0 0.0 0.0" xyz="-0.03200 0.04589 -0.06553"/>
    <axis xyz="1 0 0"/>
    <limit effort="100.0" lower="0.0" upper="1.0471975511965976" velocity="1.0"/>
    <mimic joint="gripper_left_joint" multiplier="-1.0" offset="0.0"/>
  </joint>
  <link name="gripper_left_motor_single_link">
    <visual>
      <origin rpy="0 0 0" xyz="0 0 0"/>
      <geometry>
        <mesh filename="package://talos_description/meshes/gripper/gripper_motor_single.STL" scale="1 1 1"/>
      </geometry>
      <material name="Orange"/>
    </visual>
    <collision>
      <origin rpy="0 0 0" xyz="0 0 0"/>
      <geometry>
        <mesh filename="package://talos_description/meshes/gripper/gripper_motor_single_collision.STL" scale="1 1 1"/>
      </geometry>
    </collision>
    <inertial>
      <mass value="0.107923"/>
      <inertia ixx="8.973662e-05" ixy="-4.082027e-05" ixz="-1.927099e-05" iyy="0.00011957255" iyz="-2.873284e-05" izz="0.00015469079"/>
      <origin rpy="0 0 0" xyz="0.025237 -0.011231 -0.008158"/>
    </inertial>
  </link>
  <joint name="gripper_left_motor_single_joint" type="revolute">
    <parent link="gripper_left_base_link"/>
    <child link="gripper_left_motor_single_link"/>
    <origin rpy="0.0 0.0 0.0" xyz="0.00000 -0.02025 -0.03000"/>
    <axis xyz="1 0 0"/>
    <limit effort="100.0" lower="0.0" upper="1.0471975511965976" velocity="1.0"/>
    <mimic joint="gripper_left_joint" multiplier="-1.0" offset="0.0"/>
  </joint>
  <link name="gripper_left_inner_single_link">
    <visual>
      <origin rpy="0 0 0" xyz="0 0 0"/>
      <geometry>
        <mesh filename="package://talos_description/meshes/gripper/inner_single.STL" scale="1 1 1"/>
      </geometry>
      <material name="Orange"/>
    </visual>
    <collision>
      <origin rpy="0 0 0" xyz="0 0 0"/>
      <geometry>
        <mesh filename="package://talos_description/meshes/gripper/inner_single_collision.STL" scale="1 1 1"/>
      </geometry>
    </collision>
    <inertial>
      <mass value="0.047177"/>
      <inertia ixx="4.199818e-05" ixy="1.3418e-07" ixz="1.9358e-07" iyy="3.231338e-05" iyz="-1.509136e-05" izz="2.168842e-05"/>
      <origin rpy="0 0 0" xyz="0 -0.034565 -0.021412"/>
    </inertial>
  </link>
  <joint name="gripper_left_inner_single_joint" type="revolute">
    <parent link="gripper_left_base_link"/>
    <child link="gripper_left_inner_single_link"/>
    <origin rpy="0.0 0.0 0.0" xyz="0.00000 -0.00525 -0.05598"/>
    <axis xyz="1 0 0"/>
    <limit effort="100.0" lower="0.0" upper="1.0471975511965976" velocity="1.0"/>
    <mimic joint="gripper_left_joint" multiplier="-1.0" offset="0.0"/>
  </joint>
  <link name="gripper_left_fingertip_3_link">
    <visual>
      <origin rpy="0 0 0" xyz="0 0 0"/>
      <geometry>
        <mesh filename="package://talos_description/meshes/gripper/fingertip.STL" scale="1 1 1"/>
      </geometry>
      <material name="DarkGrey"/>
    </visual>
    <collision>
      <origin rpy="0 0 0" xyz="0 0 0"/>
      <geometry>
        <mesh filename="package://talos_description/meshes/gripper/fingertip_collision.STL" scale="1 1 1"/>
      </geometry>
    </collision>
    <inertial>
      <mass value="0.026301"/>
      <inertia ixx="8e-06" ixy="0" ixz="0" iyy="8.69179e-06" iyz="-1.43612e-06" izz="2.3082e-06"/>
      <origin rpy="0 0 0" xyz="0 0.004604 -0.002537"/>
    </inertial>
  </link>
  <joint name="gripper_left_fingertip_3_joint" type="revolute">
    <parent link="gripper_left_inner_single_link"/>
    <child link="gripper_left_fingertip_3_link"/>
    <origin rpy="0.0 0.0 3.141592653589793" xyz="0.00000 -0.04589 -0.06553"/>
    <axis xyz="1 0 0"/>
    <limit effort="100.0" lower="0.0" upper="1.0471975511965976" velocity="1.0"/>
    <mimic joint="gripper_left_joint" multiplier="-1.0" offset="0.0"/>
  </joint>
  <transmission name="gripper_left_trans">
    <type>transmission_interface/SimpleTransmission</type>
    <actuator name="gripper_left_motor">
      <mechanicalReduction>1.0</mechanicalReduction>
      <hardwareInterface>hardware_interface/EffortJointInterface</hardwareInterface>
    </actuator>
    <joint name="gripper_left_joint">
      <hardwareInterface>hardware_interface/EffortJointInterface</hardwareInterface>
    </joint>
  </transmission>
  <gazebo>
    <plugin filename="libroboticsgroup_upatras_gazebo_mimic_joint_plugin.so" name="mimic_gripper_right_inner_double_joint">
      <joint>gripper_right_joint</joint>
      <mimicJoint>gripper_right_inner_double_joint</mimicJoint>
      <multiplier>1.0</multiplier>
      <offset>0.0</offset>
      <hasPID/>
    </plugin>
    <plugin filename="libroboticsgroup_upatras_gazebo_mimic_joint_plugin.so" name="mimic_gripper_right_fingertip_1_joint">
      <joint>gripper_right_joint</joint>
      <mimicJoint>gripper_right_fingertip_1_joint</mimicJoint>
      <multiplier>-1.0</multiplier>
      <offset>0.0</offset>
      <hasPID/>
    </plugin>
    <plugin filename="libroboticsgroup_upatras_gazebo_mimic_joint_plugin.so" name="mimic_gripper_right_fingertip_2_joint">
      <joint>gripper_right_joint</joint>
      <mimicJoint>gripper_right_fingertip_2_joint</mimicJoint>
      <multiplier>-1.0</multiplier>
      <offset>0.0</offset>
      <hasPID/>
    </plugin>
    <plugin filename="libroboticsgroup_upatras_gazebo_mimic_joint_plugin.so" name="mimic_gripper_right_inner_single_joint">
      <joint>gripper_right_joint</joint>
      <mimicJoint>gripper_right_inner_single_joint</mimicJoint>
      <multiplier>-1.0</multiplier>
      <offset>0.0</offset>
      <hasPID/>
    </plugin>
    <plugin filename="libroboticsgroup_upatras_gazebo_mimic_joint_plugin.so" name="mimic_gripper_right_motor_single_joint">
      <joint>gripper_right_joint</joint>
      <mimicJoint>gripper_right_motor_single_joint</mimicJoint>
      <multiplier>-1.0</multiplier>
      <offset>0.0</offset>
      <hasPID/>
    </plugin>
    <plugin filename="libroboticsgroup_upatras_gazebo_mimic_joint_plugin.so" name="mimic_gripper_right_fingertip_3_joint">
      <joint>gripper_right_joint</joint>
      <mimicJoint>gripper_right_fingertip_3_joint</mimicJoint>
      <multiplier>-1.0</multiplier>
      <offset>0.0</offset>
      <hasPID/>
    </plugin>
  </gazebo>
  <gazebo reference="gripper_right_joint">
    <implicitSpringDamper>1</implicitSpringDamper>
    <provideFeedback>1</provideFeedback>
  </gazebo>
  <gazebo reference="gripper_right_inner_double_joint">
    <implicitSpringDamper>1</implicitSpringDamper>
    <provideFeedback>1</provideFeedback>
  </gazebo>
  <gazebo reference="gripper_right_fingertip_1_joint">
    <implicitSpringDamper>1</implicitSpringDamper>
    <provideFeedback>1</provideFeedback>
  </gazebo>
  <gazebo reference="gripper_right_fingertip_2_joint">
    <implicitSpringDamper>1</implicitSpringDamper>
    <provideFeedback>1</provideFeedback>
  </gazebo>
  <gazebo reference="gripper_right_motor_single_joint">
    <implicitSpringDamper>1</implicitSpringDamper>
    <provideFeedback>1</provideFeedback>
  </gazebo>
  <gazebo reference="gripper_right_fingertip_3_joint">
    <implicitSpringDamper>1</implicitSpringDamper>
    <provideFeedback>1</provideFeedback>
  </gazebo>
  <gazebo reference="gripper_right_base_link">
    <material>Gazebo/FlatBlack</material>
  </gazebo>
  <gazebo reference="gripper_right_motor_double_link">
    <material>Gazebo/Orange</material>
  </gazebo>
  <gazebo reference="gripper_right_inner_double_link">
    <material>Gazebo/Orange</material>
  </gazebo>
  <gazebo reference="gripper_right_fingertip_1_link">
    <material>Gazebo/FlatBlack</material>
  </gazebo>
  <gazebo reference="gripper_right_motor_single_link">
    <material>Gazebo/Orange</material>
  </gazebo>
  <gazebo reference="gripper_right_inner_single_link">
    <material>Gazebo/Orange</material>
  </gazebo>
  <gazebo reference="gripper_right_fingertip_2_link">
    <material>Gazebo/FlatBlack</material>
  </gazebo>
  <gazebo reference="gripper_right_fingertip_3_link">
    <material>Gazebo/FlatBlack</material>
  </gazebo>
  <link name="gripper_right_base_link">
    <visual>
      <origin rpy="0 0 0" xyz="0 0 0"/>
      <geometry>
        <mesh filename="package://talos_description/meshes/gripper/base_link.STL" scale="1 1 1"/>
      </geometry>
      <material name="DarkGrey"/>
    </visual>
    <collision>
      <origin rpy="0 0 0" xyz="0 0 0"/>
      <geometry>
        <mesh filename="package://talos_description/meshes/gripper/base_link_collision.STL" scale="1 1 1"/>
      </geometry>
    </collision>
    <inertial>
      <mass value="0.637534"/>
      <inertia ixx="0.0005849692" ixy="4.37159e-06" ixz="-1.2589e-05" iyy="0.00067076439" iyz="2.824361e-05" izz="0.00085526645"/>
      <origin rpy="0 0 0" xyz="2.8e-05 0.005394 -0.023654"/>
    </inertial>
  </link>
  <joint name="gripper_right_base_link_joint" type="fixed">
    <parent link="wrist_right_ft_tool_link"/>
    <child link="gripper_right_base_link"/>
    <origin rpy="0.0 0.0 0.0" xyz="0.00000 0.00000 -0.02875"/>
    <axis xyz="0 0 0"/>
  </joint>
  <link name="gripper_right_motor_double_link">
    <visual>
      <origin rpy="0 0 0" xyz="0 0 0"/>
      <geometry>
        <mesh filename="package://talos_description/meshes/gripper/gripper_motor_double.STL" scale="1 1 1"/>
      </geometry>
      <material name="Orange"/>
    </visual>
    <collision>
      <origin rpy="0 0 0" xyz="0 0 0"/>
      <geometry>
        <mesh filename="package://talos_description/meshes/gripper/gripper_motor_double_collision.STL" scale="1 1 1"/>
      </geometry>
    </collision>
    <inertial>
      <mass value="0.134356"/>
      <inertia ixx="0.00013479919" ixy="6.184429e-05" ixz="-3.0798e-05" iyy="0.00019602207" iyz="4.707722e-05" izz="0.00024217879"/>
      <origin rpy="0 0 0" xyz="0.019654 0.018572 -0.011998"/>
    </inertial>
  </link>
  <joint name="gripper_right_joint" type="revolute">
    <parent link="gripper_right_base_link"/>
    <child link="gripper_right_motor_double_link"/>
    <origin rpy="0.0 0.0 0.0" xyz="0.0 0.02025 -0.03"/>
    <axis xyz="1 0 0"/>
    <limit effort="1.0" lower="-0.9599310885968813" upper="0.0" velocity="1.0"/>
    <dynamics damping="1.0" friction="1.0"/>
  </joint>
  <link name="gripper_right_inner_double_link">
    <visual>
      <origin rpy="0 0 0" xyz="0 0 0"/>
      <geometry>
        <mesh filename="package://talos_description/meshes/gripper/inner_double.STL" scale="1 1 1"/>
      </geometry>
      <material name="Orange"/>
    </visual>
    <collision>
      <origin rpy="0 0 0" xyz="0 0 0"/>
      <geometry>
        <mesh filename="package://talos_description/meshes/gripper/inner_double_collision.STL" scale="1 1 1"/>
      </geometry>
    </collision>
    <inertial>
      <mass value="0.087986"/>
      <inertia ixx="7.410642e-05" ixy="-7.4773e-07" ixz="1.01536e-06" iyy="0.0001279418" iyz="2.504083e-05" izz="0.00010495175"/>
      <origin rpy="0 0 0" xyz="-0.013283 0.036852 -0.023153"/>
    </inertial>
  </link>
  <joint name="gripper_right_inner_double_joint" type="revolute">
    <parent link="gripper_right_base_link"/>
    <child link="gripper_right_inner_double_link"/>
    <origin rpy="0.0 0.0 0.0" xyz="0.00000 0.00525 -0.05598"/>
    <axis xyz="1 0 0"/>
    <limit effort="100.0" lower="-1.0471975511965976" upper="0.0" velocity="1.0"/>
    <mimic joint="gripper_right_joint" multiplier="1.0" offset="0.0"/>
  </joint>
  <link name="gripper_right_fingertip_1_link">
    <visual>
      <origin rpy="0 0 0" xyz="0 0 0"/>
      <geometry>
        <mesh filename="package://talos_description/meshes/gripper/fingertip.STL" scale="1 1 1"/>
      </geometry>
      <material name="DarkGrey"/>
    </visual>
    <collision>
      <origin rpy="0 0 0" xyz="0 0 0"/>
      <geometry>
        <mesh filename="package://talos_description/meshes/gripper/fingertip_collision.STL" scale="1 1 1"/>
      </geometry>
    </collision>
    <inertial>
      <mass value="0.026301"/>
      <inertia ixx="8e-06" ixy="0" ixz="0" iyy="8.69179e-06" iyz="-1.43612e-06" izz="2.3082e-06"/>
      <origin rpy="0 0 0" xyz="0 0.004604 -0.002537"/>
    </inertial>
  </link>
  <joint name="gripper_right_fingertip_1_joint" type="revolute">
    <parent link="gripper_right_inner_double_link"/>
    <child link="gripper_right_fingertip_1_link"/>
    <origin rpy="0.0 0.0 0.0" xyz="0.03200 0.04589 -0.06553"/>
    <axis xyz="1 0 0"/>
    <limit effort="100.0" lower="0.0" upper="1.0471975511965976" velocity="1.0"/>
    <mimic joint="gripper_right_joint" multiplier="-1.0" offset="0.0"/>
  </joint>
  <link name="gripper_right_fingertip_2_link">
    <visual>
      <origin rpy="0 0 0" xyz="0 0 0"/>
      <geometry>
        <mesh filename="package://talos_description/meshes/gripper/fingertip.STL" scale="1 1 1"/>
      </geometry>
      <material name="DarkGrey"/>
    </visual>
    <collision>
      <origin rpy="0 0 0" xyz="0 0 0"/>
      <geometry>
        <mesh filename="package://talos_description/meshes/gripper/fingertip_collision.STL" scale="1 1 1"/>
      </geometry>
    </collision>
    <inertial>
      <mass value="0.026301"/>
      <inertia ixx="8e-06" ixy="0" ixz="0" iyy="8.69179e-06" iyz="-1.43612e-06" izz="2.3082e-06"/>
      <origin rpy="0 0 0" xyz="0 0.004604 -0.002537"/>
    </inertial>
  </link>
  <joint name="gripper_right_fingertip_2_joint" type="revolute">
    <parent link="gripper_right_inner_double_link"/>
    <child link="gripper_right_fingertip_2_link"/>
    <origin rpy="0.0 0.0 0.0" xyz="-0.03200 0.04589 -0.06553"/>
    <axis xyz="1 0 0"/>
    <limit effort="100.0" lower="0.0" upper="1.0471975511965976" velocity="1.0"/>
    <mimic joint="gripper_right_joint" multiplier="-1.0" offset="0.0"/>
  </joint>
  <link name="gripper_right_motor_single_link">
    <visual>
      <origin rpy="0 0 0" xyz="0 0 0"/>
      <geometry>
        <mesh filename="package://talos_description/meshes/gripper/gripper_motor_single.STL" scale="1 1 1"/>
      </geometry>
      <material name="Orange"/>
    </visual>
    <collision>
      <origin rpy="0 0 0" xyz="0 0 0"/>
      <geometry>
        <mesh filename="package://talos_description/meshes/gripper/gripper_motor_single_collision.STL" scale="1 1 1"/>
      </geometry>
    </collision>
    <inertial>
      <mass value="0.107923"/>
      <inertia ixx="8.973662e-05" ixy="-4.082027e-05" ixz="-1.927099e-05" iyy="0.00011957255" iyz="-2.873284e-05" izz="0.00015469079"/>
      <origin rpy="0 0 0" xyz="0.025237 -0.011231 -0.008158"/>
    </inertial>
  </link>
  <joint name="gripper_right_motor_single_joint" type="revolute">
    <parent link="gripper_right_base_link"/>
    <child link="gripper_right_motor_single_link"/>
    <origin rpy="0.0 0.0 0.0" xyz="0.00000 -0.02025 -0.03000"/>
    <axis xyz="1 0 0"/>
    <limit effort="100.0" lower="0.0" upper="1.0471975511965976" velocity="1.0"/>
    <mimic joint="gripper_right_joint" multiplier="-1.0" offset="0.0"/>
  </joint>
  <link name="gripper_right_inner_single_link">
    <visual>
      <origin rpy="0 0 0" xyz="0 0 0"/>
      <geometry>
        <mesh filename="package://talos_description/meshes/gripper/inner_single.STL" scale="1 1 1"/>
      </geometry>
      <material name="Orange"/>
    </visual>
    <collision>
      <origin rpy="0 0 0" xyz="0 0 0"/>
      <geometry>
        <mesh filename="package://talos_description/meshes/gripper/inner_single_collision.STL" scale="1 1 1"/>
      </geometry>
    </collision>
    <inertial>
      <mass value="0.047177"/>
      <inertia ixx="4.199818e-05" ixy="1.3418e-07" ixz="1.9358e-07" iyy="3.231338e-05" iyz="-1.509136e-05" izz="2.168842e-05"/>
      <origin rpy="0 0 0" xyz="0 -0.034565 -0.021412"/>
    </inertial>
  </link>
  <joint name="gripper_right_inner_single_joint" type="revolute">
    <parent link="gripper_right_base_link"/>
    <child link="gripper_right_inner_single_link"/>
    <origin rpy="0.0 0.0 0.0" xyz="0.00000 -0.00525 -0.05598"/>
    <axis xyz="1 0 0"/>
    <limit effort="100.0" lower="0.0" upper="1.0471975511965976" velocity="1.0"/>
    <mimic joint="gripper_right_joint" multiplier="-1.0" offset="0.0"/>
  </joint>
  <link name="gripper_right_fingertip_3_link">
    <visual>
      <origin rpy="0 0 0" xyz="0 0 0"/>
      <geometry>
        <mesh filename="package://talos_description/meshes/gripper/fingertip.STL" scale="1 1 1"/>
      </geometry>
      <material name="DarkGrey"/>
    </visual>
    <collision>
      <origin rpy="0 0 0" xyz="0 0 0"/>
      <geometry>
        <mesh filename="package://talos_description/meshes/gripper/fingertip_collision.STL" scale="1 1 1"/>
      </geometry>
    </collision>
    <inertial>
      <mass value="0.026301"/>
      <inertia ixx="8e-06" ixy="0" ixz="0" iyy="8.69179e-06" iyz="-1.43612e-06" izz="2.3082e-06"/>
      <origin rpy="0 0 0" xyz="0 0.004604 -0.002537"/>
    </inertial>
  </link>
  <joint name="gripper_right_fingertip_3_joint" type="revolute">
    <parent link="gripper_right_inner_single_link"/>
    <child link="gripper_right_fingertip_3_link"/>
    <origin rpy="0.0 0.0 3.141592653589793" xyz="0.00000 -0.04589 -0.06553"/>
    <axis xyz="1 0 0"/>
    <limit effort="100.0" lower="0.0" upper="1.0471975511965976" velocity="1.0"/>
    <mimic joint="gripper_right_joint" multiplier="-1.0" offset="0.0"/>
  </joint>
  <transmission name="gripper_right_trans">
    <type>transmission_interface/SimpleTransmission</type>
    <actuator name="gripper_right_motor">
      <mechanicalReduction>1.0</mechanicalReduction>
      <hardwareInterface>hardware_interface/EffortJointInterface</hardwareInterface>
    </actuator>
    <joint name="gripper_right_joint">
      <hardwareInterface>hardware_interface/EffortJointInterface</hardwareInterface>
    </joint>
  </transmission>
  <gazebo>
    <plugin filename="libgazebo_ros_control.so" name="gazebo_ros_control">
      <robotNamespace>/talos</robotNamespace>
      <robotSimType>gazebo_ros_control/DefaultRobotHWSim</robotSimType>
    </plugin>
  </gazebo>
  <gazebo>
    <plugin filename="libOrbit_robot_pkg_plugin.so" name="Orbit_robot_pkg_plugin"/>
  </gazebo>
  <gazebo>
    <plugin filename="libgazebo_ros_force.so" name="gazebo_ros_force">
      <bodyName>base_link</bodyName>
      <topicName>wrench</topicName>
    </plugin>
  </gazebo>
  <gazebo reference="imu_link">
    <sensor name="imu_sensor" type="imu">
      <always_on>1</always_on>
      <update_rate>1000.0</update_rate>
      <imu>
        <noise>
          <type>gaussian</type>
          <rate>
            <mean>0.0</mean>
            <stddev>0.0</stddev>
            <bias_mean>0.000000</bias_mean>
            <bias_stddev>0.0000008</bias_stddev>
          </rate>
          <accel>
            <mean>0.0</mean>
            <stddev>0.0</stddev>
            <bias_mean>0.0</bias_mean>
            <bias_stddev>0.000</bias_stddev>
          </accel>
        </noise>
      </imu>
    </sensor>
  </gazebo>
  <material name="Blue">
    <color rgba="0.0 0.0 0.8 1.0"/>
  </material>
  <material name="Green">
    <color rgba="0.0 0.8 0.0 1.0"/>
  </material>
  <material name="Grey">
    <color rgba="0.7 0.7 0.7 1.0"/>
  </material>
  <material name="LightGrey">
    <color rgba="0.9 0.9 0.9 1.0"/>
  </material>
  <material name="DarkGrey">
    <color rgba="0.2 0.2 0.2 1.0"/>
  </material>
  <material name="Red">
    <color rgba="0.8 0.0 0.0 1.0"/>
  </material>
  <material name="White">
    <color rgba="1.0 1.0 1.0 1.0"/>
  </material>
  <material name="Orange">
    <color rgba="1.0 0.5 0.0 1.0"/>
  </material>
  <material name="FlatBlack">
    <color rgba="1.0 0.0 0.0 0.0"/>
  </material>
</robot>
